Workbook

Sheet 요약
A1: 기준사양 매칭 요약 — 연간 구매수량 기준 (특가)
A3: 시스템 | B3: 기존 사양 (ABB) | C3: 연간 구매수량 (EA) | D3: 안A: 24VDC + Relay (1 set) | E3: 안B: DC24V 최저가 (1 set) | F3: 안C: AC220V CPU (1 set) | G3: 안A 연간 금액 | H3: 안B 연간 금액 | I3: 안C 연간 금액
A4: TSU | B4: ABB PM554-RP + DO571 | C4: 200 | D4: ='기준사양 매칭'!G9 -> 457250 | E4: ='기준사양 매칭'!G11 -> 392850 | F4: ='기준사양 매칭'!G13 -> 384750 | G4: =$C4*D4 -> 91450000 | H4: =$C4*E4 -> 78570000 | I4: =$C4*F4 -> 76950000
A5: ANU | B5: ABB PM554-RP + DO571 + AO561 | C5: 300 | D5: ='기준사양 매칭'!G20 -> 622050 | E5: ='기준사양 매칭'!G23 -> 556000 | F5: ='기준사양 매칭'!G26 -> 544750 | G5: =$C5*D5 -> 186615000 | H5: =$C5*E5 -> 166800000 | I5: =$C5*F5 -> 163425000
A6: ANU-S | B6: ABB PM564-RP | C6: 50 | D6: ='기준사양 매칭'!G33 -> 595650 | E6: ='기준사양 매칭'!G36 -> 531250 | F6: ='기준사양 매칭'!G39 -> 523150 | G6: =$C6*D6 -> 29782500 | H6: =$C6*E6 -> 26562500 | I6: =$C6*F6 -> 26157500
A7: MCC | B7: ABB PM564-RP-ETH + DI562×6 + DO573×3 + AO561×2 | C7: 100 | D7: ='기준사양 매칭'!G47 -> 1449500 | E7: ='기준사양 매칭'!G52 -> 1449500 | F7: ='기준사양 매칭'!G57 -> 1449500 | G7: =$C7*D7 -> 144950000 | H7: =$C7*E7 -> 144950000 | I7: =$C7*F7 -> 144950000
A8: 합계 | C8: =SUM(C4:C7) -> 650 | D8: =SUM(D4:D7) -> 3124450 | E8: =SUM(E4:E7) -> 2929600 | F8: =SUM(F4:F7) -> 2902150 | G8: =SUM(G4:G7) -> 452797500 | H8: =SUM(H4:H7) -> 416882500 | I8: =SUM(I4:I7) -> 411482500
A9: 안A 대비 연간 차액 | G9: =G8-$G$8 -> 0 | H9: =H8-$G$8 -> -35915000 | I9: =I8-$G$8 -> -41315000
A11: • 기준: Techross RFQ 'PLC 사양서 R3.1' — 필수 DI/DO +10% Spare, TSU/ANU/ANU-S는 Relay·Tr 모두 가능 + AC220V/DC24V(권장) 각각 견적, MCC는 DC24V + Relay Type Only.
A12: • 안A: 기존 ABB와 같은 DC24V + Relay 출력 → 현장 배선·부하 변경 최소화. CPU 내장 Tr 출력은 Spare.
A13: • 안B: RFQ 권장 전압(DC24V) 중 최저가 — TSU/ANU/ANU-S는 Tr 출력, MCC는 RFQ에 따라 Relay(안A와 동일 구성).
A14: • 안C: TSU/ANU/ANU-S를 AC220V CPU(TM241C24R/C40R, Relay 6/12 + Tr 4)로. MCC는 DC24V 필수라 안A와 동일.
A15: • MCC는 TM3 모듈 11개로 로컬 한도 7개 초과 → TM3XTRA1 + TM3XREC1 버스 확장(가격표 미포함) 또는 고밀도 모듈 견적 필요.
A16: • ANU 요구표엔 AO가 없지만 기존 하드웨어(AO561)를 따라 TM3AQ2 반영 — 미사용이면 각 안에서 138,400 차감.
A17: • 연간 구매수량(파란 글씨)은 RFQ 값: TSU 200 / ANU 300 / ANU-S 50 / MCC 100 EA. 수량을 바꾸면 연간 금액과 '연간 BOM'이 함께 재계산됨.
A18: • 파란 글씨 = 입력값, 초록 = 다른 시트 참조. 단가는 사용자 제공 특가(2027년 기준 여부 확인 필요), I/O 사양은 Schneider 카탈로그 기준.

Sheet Price List
A1: No. | B1: Activity | C1: Material | D1: DC/AC | E1: Q'ty | F1: Unit List Price | H1: <Funding> Special DF | K1: I/O Spec (매칭용)
F2: Unit Price | G2: Total Amount | H2: Special Discount Factor | I2: Unit Price | J2: Total Amount | K2: DI | L2: DO (Tr) | M2: DO (Relay) | N2: AI | O2: AO | P2: Serial | Q2: Ethernet | R2: 비고
A3: 1 | B3: IDMST | C3: TM241CE24T | D3: DC | E3: 1 | F3: 886000 | G3: =E3*F3 -> 886000 | H3: 0.45 | I3: =ROUND(F3*H3,0) -> 398700 | J3: =E3*I3 -> 398700 | K3: 14 | L3: 10 | M3: 0 | N3: 0 | O3: 0 | P3: 2 | Q3: 1 | R3: CPU, Ethernet, 24VDC
A4: 2 | B4: IDMST | C4: TM241C24T | D4: DC | E4: 1 | F4: 873000 | G4: =E4*F4 -> 873000 | H4: 0.45 | I4: =ROUND(F4*H4,0) -> 392850 | J4: =E4*I4 -> 392850 | K4: 14 | L4: 10 | M4: 0 | N4: 0 | O4: 0 | P4: 2 | Q4: 0 | R4: CPU, 24VDC
A5: 3 | B5: IDMST | C5: TM241C24R | D5: AC | E5: 1 | F5: 855000 | G5: =E5*F5 -> 855000 | H5: 0.45 | I5: =ROUND(F5*H5,0) -> 384750 | J5: =E5*I5 -> 384750 | K5: 14 | L5: 4 | M5: 6 | N5: 0 | O5: 0 | P5: 2 | Q5: 0 | R5: CPU, 100-240VAC
A6: 4 | B6: IDMST | C6: TM241C40T | D6: DC | E6: 1 | F6: 928000 | G6: =E6*F6 -> 928000 | H6: 0.45 | I6: =ROUND(F6*H6,0) -> 417600 | J6: =E6*I6 -> 417600 | K6: 24 | L6: 16 | M6: 0 | N6: 0 | O6: 0 | P6: 2 | Q6: 0 | R6: CPU, 24VDC
A7: 5 | B7: IDMST | C7: TM241C40R | D7: AC | E7: 1 | F7: 903000 | G7: =E7*F7 -> 903000 | H7: 0.45 | I7: =ROUND(F7*H7,0) -> 406350 | J7: =E7*I7 -> 406350 | K7: 24 | L7: 4 | M7: 12 | N7: 0 | O7: 0 | P7: 2 | Q7: 0 | R7: CPU, 100-240VAC
A8: 6 | B8: IDMST | C8: TM3DI16 | E8: 1 | F8: 228000 | G8: =E8*F8 -> 228000 | H8: 0.4 | I8: =ROUND(F8*H8,0) -> 91200 | J8: =E8*I8 -> 91200 | K8: 16 | L8: 0 | M8: 0 | N8: 0 | O8: 0 | P8: 0 | Q8: 0 | R8: DI 16
A9: 7 | B9: IDMST | C9: TM3DI8 | E9: 1 | F9: 202000 | G9: =E9*F9 -> 202000 | H9: 0.4 | I9: =ROUND(F9*H9,0) -> 80800 | J9: =E9*I9 -> 80800 | K9: 8 | L9: 0 | M9: 0 | N9: 0 | O9: 0 | P9: 0 | Q9: 0 | R9: DI 8
A10: 8 | B10: IDMST | C10: TM3DQ16R | E10: 1 | F10: 227000 | G10: =E10*F10 -> 227000 | H10: 0.4 | I10: =ROUND(F10*H10,0) -> 90800 | J10: =E10*I10 -> 90800 | K10: 0 | L10: 0 | M10: 16 | N10: 0 | O10: 0 | P10: 0 | Q10: 0 | R10: DO 16 Relay
A11: 9 | B11: IDMST | C11: TM3DQ16T | E11: 1 | F11: 227000 | G11: =E11*F11 -> 227000 | H11: 0.4 | I11: =ROUND(F11*H11,0) -> 90800 | J11: =E11*I11 -> 90800 | K11: 0 | L11: 16 | M11: 0 | N11: 0 | O11: 0 | P11: 0 | Q11: 0 | R11: DO 16 Tr (Source)
A12: 10 | B12: IDMST | C12: TM3DQ16U | E12: 1 | F12: 213000 | G12: =E12*F12 -> 213000 | H12: 0.4 | I12: =ROUND(F12*H12,0) -> 85200 | J12: =E12*I12 -> 85200 | K12: 0 | L12: 16 | M12: 0 | N12: 0 | O12: 0 | P12: 0 | Q12: 0 | R12: DO 16 Tr (Sink)
A13: 11 | B13: IDMST | C13: TM3DQ8R | E13: 1 | F13: 161000 | G13: =E13*F13 -> 161000 | H13: 0.4 | I13: =ROUND(F13*H13,0) -> 64400 | J13: =E13*I13 -> 64400 | K13: 0 | L13: 0 | M13: 8 | N13: 0 | O13: 0 | P13: 0 | Q13: 0 | R13: DO 8 Relay
A14: 12 | B14: IDMST | C14: TM3DQ8T | E14: 1 | F14: 168000 | G14: =E14*F14 -> 168000 | H14: 0.4 | I14: =ROUND(F14*H14,0) -> 67200 | J14: =E14*I14 -> 67200 | K14: 0 | L14: 8 | M14: 0 | N14: 0 | O14: 0 | P14: 0 | Q14: 0 | R14: DO 8 Tr (Source)
A15: 13 | B15: IDMST | C15: TM3DQ8U | E15: 1 | F15: 168000 | G15: =E15*F15 -> 168000 | H15: 0.4 | I15: =ROUND(F15*H15,0) -> 67200 | J15: =E15*I15 -> 67200 | K15: 0 | L15: 8 | M15: 0 | N15: 0 | O15: 0 | P15: 0 | Q15: 0 | R15: DO 8 Tr (Sink)
A16: 14 | B16: IDMST | C16: TM3AI2H | E16: 1 | F16: 311000 | G16: =E16*F16 -> 311000 | H16: 0.4 | I16: =ROUND(F16*H16,0) -> 124400 | J16: =E16*I16 -> 124400 | K16: 0 | L16: 0 | M16: 0 | N16: 2 | O16: 0 | P16: 0 | Q16: 0 | R16: AI 2 (16bit)
A17: 15 | B17: IDMST | C17: TM3AI4 | E17: 1 | F17: 284000 | G17: =E17*F17 -> 284000 | H17: 0.4 | I17: =ROUND(F17*H17,0) -> 113600 | J17: =E17*I17 -> 113600 | K17: 0 | L17: 0 | M17: 0 | N17: 4 | O17: 0 | P17: 0 | Q17: 0 | R17: AI 4
A18: 16 | B18: IDMST | C18: TM3AI8 | E18: 1 | F18: 331000 | G18: =E18*F18 -> 331000 | H18: 0.4 | I18: =ROUND(F18*H18,0) -> 132400 | J18: =E18*I18 -> 132400 | K18: 0 | L18: 0 | M18: 0 | N18: 8 | O18: 0 | P18: 0 | Q18: 0 | R18: AI 8
A19: 17 | B19: IDMST | C19: TM3AQ2 | E19: 1 | F19: 346000 | G19: =E19*F19 -> 346000 | H19: 0.4 | I19: =ROUND(F19*H19,0) -> 138400 | J19: =E19*I19 -> 138400 | K19: 0 | L19: 0 | M19: 0 | N19: 0 | O19: 2 | P19: 0 | Q19: 0 | R19: AO 2
A20: 18 | B20: IDMST | C20: TM3AQ4 | E20: 1 | F20: 351000 | G20: =E20*F20 -> 351000 | H20: 0.4 | I20: =ROUND(F20*H20,0) -> 140400 | J20: =E20*I20 -> 140400 | K20: 0 | L20: 0 | M20: 0 | N20: 0 | O20: 4 | P20: 0 | Q20: 0 | R20: AO 4
A21: Total | E21: =SUM(E3:E20) -> 18 | G21: =SUM(G3:G20) -> 7662000 | H21: =IFERROR(J21/G21,0) -> 0.42900679 | J21: =SUM(J3:J20) -> 3287050
A23: Notes: 파란 글씨 = 입력값. A~J열 가격은 사용자 제공 견적 그대로 (18번 Total은 원본에서 '140,40'으로 잘려 수식으로 140,400 계산). K~Q열 I/O 사양은 Schneider Modicon M241/TM3 카탈로그 기준으로 Claude가 입력한 값 — 발주 전 최신 카탈로그로 확인 필요. TM241C24R/C40R의 출력은 Relay + 고속 Tr 4점 혼합.

Sheet 기준사양 매칭
A1: 기준사양 매칭 — 기존 ABB AC500-eCo → Schneider M241/TM3 (특가 기준, 1 set당)
A2: 단가는 'Price List' 시트 특가(Unit Price, Special DF 적용)를 INDEX/MATCH로 참조. 요구 점수 = RFQ(PLC 사양서 R3.1) 필수 점수 +10% Spare(올림). MCC는 현행 유지 점수. 판정: 점수 충족 + 안A 및 MCC(RFQ: Relay Type Only)는 Relay 출력 점수가 DO 요구 이상인지 확인. M241 로컬 확장은 TM3 모듈 7개까지 — 초과 시 TM3XTRA1/TM3XREC1 버스 확장 필요(가격표 미포함).
A4: 시스템 | B4: 구성안 | C4: Material | D4: 설명 / 대체 기존품 | E4: Q'ty | F4: 특가 단가 | G4: 금액 | H4: DI | I4: DO (Tr) | J4: DO (Relay) | K4: DO 합계 | L4: AO | M4: Serial | N4: Ethernet | O4: TM3 모듈수 | P4: 판정 | Q4: 연간 수량 (EA)
A5: TSU | 기존: ABB PM554-RP + DO571
A6: TSU | B6: 요구 사양 | D6: 기존 사양표 기준 요구 점수 | H6: 4 | K6: 7 | L6: 0 | M6: 2 | N6: 0
A7: TSU | B7: A | C7: TM241C24T | D7: CPU (PM554-RP 대체) | E7: 1 | F7: =INDEX('Price List'!$I$3:$I$20,MATCH($C7,'Price List'!$C$3:$C$20,0)) -> 392850 | G7: =E7*F7 -> 392850 | H7: =E7*INDEX('Price List'!$K$3:$K$20,MATCH($C7,'Price List'!$C$3:$C$20,0)) -> 14 | I7: =E7*INDEX('Price List'!$L$3:$L$20,MATCH($C7,'Price List'!$C$3:$C$20,0)) -> 10 | J7: =E7*INDEX('Price List'!$M$3:$M$20,MATCH($C7,'Price List'!$C$3:$C$20,0)) -> 0 | K7: =I7+J7 -> 10 | L7: =E7*INDEX('Price List'!$O$3:$O$20,MATCH($C7,'Price List'!$C$3:$C$20,0)) -> 0 | M7: =E7*INDEX('Price List'!$P$3:$P$20,MATCH($C7,'Price List'!$C$3:$C$20,0)) -> 2 | N7: =E7*INDEX('Price List'!$Q$3:$Q$20,MATCH($C7,'Price List'!$C$3:$C$20,0)) -> 0 | O7: =IF(LEFT(C7,3)="TM3",E7,0) -> 0 | Q7: =E7*INDEX(요약!$C$4:$C$7,MATCH($A7,요약!$A$4:$A$7,0)) -> 200
A8: TSU | B8: A | C8: TM3DQ8R | D8: Relay DO8 (DO571 대체) | E8: 1 | F8: =INDEX('Price List'!$I$3:$I$20,MATCH($C8,'Price List'!$C$3:$C$20,0)) -> 64400 | G8: =E8*F8 -> 64400 | H8: =E8*INDEX('Price List'!$K$3:$K$20,MATCH($C8,'Price List'!$C$3:$C$20,0)) -> 0 | I8: =E8*INDEX('Price List'!$L$3:$L$20,MATCH($C8,'Price List'!$C$3:$C$20,0)) -> 0 | J8: =E8*INDEX('Price List'!$M$3:$M$20,MATCH($C8,'Price List'!$C$3:$C$20,0)) -> 8 | K8: =I8+J8 -> 8 | L8: =E8*INDEX('Price List'!$O$3:$O$20,MATCH($C8,'Price List'!$C$3:$C$20,0)) -> 0 | M8: =E8*INDEX('Price List'!$P$3:$P$20,MATCH($C8,'Price List'!$C$3:$C$20,0)) -> 0 | N8: =E8*INDEX('Price List'!$Q$3:$Q$20,MATCH($C8,'Price List'!$C$3:$C$20,0)) -> 0 | O8: =IF(LEFT(C8,3)="TM3",E8,0) -> 1 | Q8: =E8*INDEX(요약!$C$4:$C$7,MATCH($A8,요약!$A$4:$A$7,0)) -> 200
A9: TSU | B9: A | C9: 소계 | D9: 안A: 24VDC + Relay 출력 (기존 ABB와 동일 방식) | G9: =SUM(G7:G8) -> 457250 | H9: =SUM(H7:H8) -> 14 | I9: =SUM(I7:I8) -> 10 | J9: =SUM(J7:J8) -> 8 | K9: =SUM(K7:K8) -> 18 | L9: =SUM(L7:L8) -> 0 | M9: =SUM(M7:M8) -> 2 | N9: =SUM(N7:N8) -> 0 | O9: =SUM(O7:O8) -> 1 | P9: =IF(AND(H9>=H6,K9>=K6,J9>=K6,L9>=L6,M9>=M6,N9>=N6),IF(O9>7,"OK (TM3 버스확장 필요)","OK"),"사양 미달") -> OK
A10: TSU | B10: B | C10: TM241C24T | D10: CPU, Tr DO10 (PM554-RP+DO571 대체) | E10: 1 | F10: =INDEX('Price List'!$I$3:$I$20,MATCH($C10,'Price List'!$C$3:$C$20,0)) -> 392850 | G10: =E10*F10 -> 392850 | H10: =E10*INDEX('Price List'!$K$3:$K$20,MATCH($C10,'Price List'!$C$3:$C$20,0)) -> 14 | I10: =E10*INDEX('Price List'!$L$3:$L$20,MATCH($C10,'Price List'!$C$3:$C$20,0)) -> 10 | J10: =E10*INDEX('Price List'!$M$3:$M$20,MATCH($C10,'Price List'!$C$3:$C$20,0)) -> 0 | K10: =I10+J10 -> 10 | L10: =E10*INDEX('Price List'!$O$3:$O$20,MATCH($C10,'Price List'!$C$3:$C$20,0)) -> 0 | M10: =E10*INDEX('Price List'!$P$3:$P$20,MATCH($C10,'Price List'!$C$3:$C$20,0)) -> 2 | N10: =E10*INDEX('Price List'!$Q$3:$Q$20,MATCH($C10,'Price List'!$C$3:$C$20,0)) -> 0 | O10: =IF(LEFT(C10,3)="TM3",E10,0) -> 0 | Q10: =E10*INDEX(요약!$C$4:$C$7,MATCH($A10,요약!$A$4:$A$7,0)) -> 200
A11: TSU | B11: B | C11: 소계 | D11: 안B: DC24V 최저가 (TSU/ANU/ANU-S Tr, MCC Relay) | G11: =SUM(G10:G10) -> 392850 | H11: =SUM(H10:H10) -> 14 | I11: =SUM(I10:I10) -> 10 | J11: =SUM(J10:J10) -> 0 | K11: =SUM(K10:K10) -> 10 | L11: =SUM(L10:L10) -> 0 | M11: =SUM(M10:M10) -> 2 | N11: =SUM(N10:N10) -> 0 | O11: =SUM(O10:O10) -> 0 | P11: =IF(AND(H11>=H6,K11>=K6,TRUE(),L11>=L6,M11>=M6,N11>=N6),IF(O11>7,"OK (TM3 버스확장 필요)","OK"),"사양 미달") -> OK
A12: TSU | B12: C | C12: TM241C24R | D12: CPU, Relay DO6 + Tr4 (PM554-RP+DO571 대체) | E12: 1 | F12: =INDEX('Price List'!$I$3:$I$20,MATCH($C12,'Price List'!$C$3:$C$20,0)) -> 384750 | G12: =E12*F12 -> 384750 | H12: =E12*INDEX('Price List'!$K$3:$K$20,MATCH($C12,'Price List'!$C$3:$C$20,0)) -> 14 | I12: =E12*INDEX('Price List'!$L$3:$L$20,MATCH($C12,'Price List'!$C$3:$C$20,0)) -> 4 | J12: =E12*INDEX('Price List'!$M$3:$M$20,MATCH($C12,'Price List'!$C$3:$C$20,0)) -> 6 | K12: =I12+J12 -> 10 | L12: =E12*INDEX('Price List'!$O$3:$O$20,MATCH($C12,'Price List'!$C$3:$C$20,0)) -> 0 | M12: =E12*INDEX('Price List'!$P$3:$P$20,MATCH($C12,'Price List'!$C$3:$C$20,0)) -> 2 | N12: =E12*INDEX('Price List'!$Q$3:$Q$20,MATCH($C12,'Price List'!$C$3:$C$20,0)) -> 0 | O12: =IF(LEFT(C12,3)="TM3",E12,0) -> 0 | Q12: =E12*INDEX(요약!$C$4:$C$7,MATCH($A12,요약!$A$4:$A$7,0)) -> 200
A13: TSU | B13: C | C13: 소계 | D13: 안C: AC220V CPU + Relay (MCC는 DC24V Relay) | G13: =SUM(G12:G12) -> 384750 | H13: =SUM(H12:H12) -> 14 | I13: =SUM(I12:I12) -> 4 | J13: =SUM(J12:J12) -> 6 | K13: =SUM(K12:K12) -> 10 | L13: =SUM(L12:L12) -> 0 | M13: =SUM(M12:M12) -> 2 | N13: =SUM(N12:N12) -> 0 | O13: =SUM(O12:O12) -> 0 | P13: =IF(AND(H13>=H6,K13>=K6,TRUE(),L13>=L6,M13>=M6,N13>=N6),IF(O13>7,"OK (TM3 버스확장 필요)","OK"),"사양 미달") -> OK
A15: ANU | 기존: ABB PM554-RP + DO571 + AO561
A16: ANU | B16: 요구 사양 | D16: 기존 사양표 기준 요구 점수 | H16: 7 | K16: 14 | L16: 2 | M16: 2 | N16: 0
A17: ANU | B17: A | C17: TM241C24T | D17: CPU (PM554-RP 대체) | E17: 1 | F17: =INDEX('Price List'!$I$3:$I$20,MATCH($C17,'Price List'!$C$3:$C$20,0)) -> 392850 | G17: =E17*F17 -> 392850 | H17: =E17*INDEX('Price List'!$K$3:$K$20,MATCH($C17,'Price List'!$C$3:$C$20,0)) -> 14 | I17: =E17*INDEX('Price List'!$L$3:$L$20,MATCH($C17,'Price List'!$C$3:$C$20,0)) -> 10 | J17: =E17*INDEX('Price List'!$M$3:$M$20,MATCH($C17,'Price List'!$C$3:$C$20,0)) -> 0 | K17: =I17+J17 -> 10 | L17: =E17*INDEX('Price List'!$O$3:$O$20,MATCH($C17,'Price List'!$C$3:$C$20,0)) -> 0 | M17: =E17*INDEX('Price List'!$P$3:$P$20,MATCH($C17,'Price List'!$C$3:$C$20,0)) -> 2 | N17: =E17*INDEX('Price List'!$Q$3:$Q$20,MATCH($C17,'Price List'!$C$3:$C$20,0)) -> 0 | O17: =IF(LEFT(C17,3)="TM3",E17,0) -> 0 | Q17: =E17*INDEX(요약!$C$4:$C$7,MATCH($A17,요약!$A$4:$A$7,0)) -> 300
A18: ANU | B18: A | C18: TM3DQ16R | D18: Relay DO16 (DO571 대체) | E18: 1 | F18: =INDEX('Price List'!$I$3:$I$20,MATCH($C18,'Price List'!$C$3:$C$20,0)) -> 90800 | G18: =E18*F18 -> 90800 | H18: =E18*INDEX('Price List'!$K$3:$K$20,MATCH($C18,'Price List'!$C$3:$C$20,0)) -> 0 | I18: =E18*INDEX('Price List'!$L$3:$L$20,MATCH($C18,'Price List'!$C$3:$C$20,0)) -> 0 | J18: =E18*INDEX('Price List'!$M$3:$M$20,MATCH($C18,'Price List'!$C$3:$C$20,0)) -> 16 | K18: =I18+J18 -> 16 | L18: =E18*INDEX('Price List'!$O$3:$O$20,MATCH($C18,'Price List'!$C$3:$C$20,0)) -> 0 | M18: =E18*INDEX('Price List'!$P$3:$P$20,MATCH($C18,'Price List'!$C$3:$C$20,0)) -> 0 | N18: =E18*INDEX('Price List'!$Q$3:$Q$20,MATCH($C18,'Price List'!$C$3:$C$20,0)) -> 0 | O18: =IF(LEFT(C18,3)="TM3",E18,0) -> 1 | Q18: =E18*INDEX(요약!$C$4:$C$7,MATCH($A18,요약!$A$4:$A$7,0)) -> 300
A19: ANU | B19: A | C19: TM3AQ2 | D19: AO2 (AO561 대체) | E19: 1 | F19: =INDEX('Price List'!$I$3:$I$20,MATCH($C19,'Price List'!$C$3:$C$20,0)) -> 138400 | G19: =E19*F19 -> 138400 | H19: =E19*INDEX('Price List'!$K$3:$K$20,MATCH($C19,'Price List'!$C$3:$C$20,0)) -> 0 | I19: =E19*INDEX('Price List'!$L$3:$L$20,MATCH($C19,'Price List'!$C$3:$C$20,0)) -> 0 | J19: =E19*INDEX('Price List'!$M$3:$M$20,MATCH($C19,'Price List'!$C$3:$C$20,0)) -> 0 | K19: =I19+J19 -> 0 | L19: =E19*INDEX('Price List'!$O$3:$O$20,MATCH($C19,'Price List'!$C$3:$C$20,0)) -> 2 | M19: =E19*INDEX('Price List'!$P$3:$P$20,MATCH($C19,'Price List'!$C$3:$C$20,0)) -> 0 | N19: =E19*INDEX('Price List'!$Q$3:$Q$20,MATCH($C19,'Price List'!$C$3:$C$20,0)) -> 0 | O19: =IF(LEFT(C19,3)="TM3",E19,0) -> 1 | Q19: =E19*INDEX(요약!$C$4:$C$7,MATCH($A19,요약!$A$4:$A$7,0)) -> 300
A20: ANU | B20: A | C20: 소계 | D20: 안A: 24VDC + Relay 출력 (기존 ABB와 동일 방식) | G20: =SUM(G17:G19) -> 622050 | H20: =SUM(H17:H19) -> 14 | I20: =SUM(I17:I19) -> 10 | J20: =SUM(J17:J19) -> 16 | K20: =SUM(K17:K19) -> 26 | L20: =SUM(L17:L19) -> 2 | M20: =SUM(M17:M19) -> 2 | N20: =SUM(N17:N19) -> 0 | O20: =SUM(O17:O19) -> 2 | P20: =IF(AND(H20>=H16,K20>=K16,J20>=K16,L20>=L16,M20>=M16,N20>=N16),IF(O20>7,"OK (TM3 버스확장 필요)","OK"),"사양 미달") -> OK
A21: ANU | B21: B | C21: TM241C40T | D21: CPU 24DI/16DO Tr (PM554-RP+DO571 대체) | E21: 1 | F21: =INDEX('Price List'!$I$3:$I$20,MATCH($C21,'Price List'!$C$3:$C$20,0)) -> 417600 | G21: =E21*F21 -> 417600 | H21: =E21*INDEX('Price List'!$K$3:$K$20,MATCH($C21,'Price List'!$C$3:$C$20,0)) -> 24 | I21: =E21*INDEX('Price List'!$L$3:$L$20,MATCH($C21,'Price List'!$C$3:$C$20,0)) -> 16 | J21: =E21*INDEX('Price List'!$M$3:$M$20,MATCH($C21,'Price List'!$C$3:$C$20,0)) -> 0 | K21: =I21+J21 -> 16 | L21: =E21*INDEX('Price List'!$O$3:$O$20,MATCH($C21,'Price List'!$C$3:$C$20,0)) -> 0 | M21: =E21*INDEX('Price List'!$P$3:$P$20,MATCH($C21,'Price List'!$C$3:$C$20,0)) -> 2 | N21: =E21*INDEX('Price List'!$Q$3:$Q$20,MATCH($C21,'Price List'!$C$3:$C$20,0)) -> 0 | O21: =IF(LEFT(C21,3)="TM3",E21,0) -> 0 | Q21: =E21*INDEX(요약!$C$4:$C$7,MATCH($A21,요약!$A$4:$A$7,0)) -> 300
A22: ANU | B22: B | C22: TM3AQ2 | D22: AO2 (AO561 대체) | E22: 1 | F22: =INDEX('Price List'!$I$3:$I$20,MATCH($C22,'Price List'!$C$3:$C$20,0)) -> 138400 | G22: =E22*F22 -> 138400 | H22: =E22*INDEX('Price List'!$K$3:$K$20,MATCH($C22,'Price List'!$C$3:$C$20,0)) -> 0 | I22: =E22*INDEX('Price List'!$L$3:$L$20,MATCH($C22,'Price List'!$C$3:$C$20,0)) -> 0 | J22: =E22*INDEX('Price List'!$M$3:$M$20,MATCH($C22,'Price List'!$C$3:$C$20,0)) -> 0 | K22: =I22+J22 -> 0 | L22: =E22*INDEX('Price List'!$O$3:$O$20,MATCH($C22,'Price List'!$C$3:$C$20,0)) -> 2 | M22: =E22*INDEX('Price List'!$P$3:$P$20,MATCH($C22,'Price List'!$C$3:$C$20,0)) -> 0 | N22: =E22*INDEX('Price List'!$Q$3:$Q$20,MATCH($C22,'Price List'!$C$3:$C$20,0)) -> 0 | O22: =IF(LEFT(C22,3)="TM3",E22,0) -> 1 | Q22: =E22*INDEX(요약!$C$4:$C$7,MATCH($A22,요약!$A$4:$A$7,0)) -> 300
A23: ANU | B23: B | C23: 소계 | D23: 안B: DC24V 최저가 (TSU/ANU/ANU-S Tr, MCC Relay) | G23: =SUM(G21:G22) -> 556000 | H23: =SUM(H21:H22) -> 24 | I23: =SUM(I21:I22) -> 16 | J23: =SUM(J21:J22) -> 0 | K23: =SUM(K21:K22) -> 16 | L23: =SUM(L21:L22) -> 2 | M23: =SUM(M21:M22) -> 2 | N23: =SUM(N21:N22) -> 0 | O23: =SUM(O21:O22) -> 1 | P23: =IF(AND(H23>=H16,K23>=K16,TRUE(),L23>=L16,M23>=M16,N23>=N16),IF(O23>7,"OK (TM3 버스확장 필요)","OK"),"사양 미달") -> OK
A24: ANU | B24: C | C24: TM241C40R | D24: CPU 24DI / Relay12+Tr4 (PM554-RP+DO571 대체) | E24: 1 | F24: =INDEX('Price List'!$I$3:$I$20,MATCH($C24,'Price List'!$C$3:$C$20,0)) -> 406350 | G24: =E24*F24 -> 406350 | H24: =E24*INDEX('Price List'!$K$3:$K$20,MATCH($C24,'Price List'!$C$3:$C$20,0)) -> 24 | I24: =E24*INDEX('Price List'!$L$3:$L$20,MATCH($C24,'Price List'!$C$3:$C$20,0)) -> 4 | J24: =E24*INDEX('Price List'!$M$3:$M$20,MATCH($C24,'Price List'!$C$3:$C$20,0)) -> 12 | K24: =I24+J24 -> 16 | L24: =E24*INDEX('Price List'!$O$3:$O$20,MATCH($C24,'Price List'!$C$3:$C$20,0)) -> 0 | M24: =E24*INDEX('Price List'!$P$3:$P$20,MATCH($C24,'Price List'!$C$3:$C$20,0)) -> 2 | N24: =E24*INDEX('Price List'!$Q$3:$Q$20,MATCH($C24,'Price List'!$C$3:$C$20,0)) -> 0 | O24: =IF(LEFT(C24,3)="TM3",E24,0) -> 0 | Q24: =E24*INDEX(요약!$C$4:$C$7,MATCH($A24,요약!$A$4:$A$7,0)) -> 300
A25: ANU | B25: C | C25: TM3AQ2 | D25: AO2 (AO561 대체) | E25: 1 | F25: =INDEX('Price List'!$I$3:$I$20,MATCH($C25,'Price List'!$C$3:$C$20,0)) -> 138400 | G25: =E25*F25 -> 138400 | H25: =E25*INDEX('Price List'!$K$3:$K$20,MATCH($C25,'Price List'!$C$3:$C$20,0)) -> 0 | I25: =E25*INDEX('Price List'!$L$3:$L$20,MATCH($C25,'Price List'!$C$3:$C$20,0)) -> 0 | J25: =E25*INDEX('Price List'!$M$3:$M$20,MATCH($C25,'Price List'!$C$3:$C$20,0)) -> 0 | K25: =I25+J25 -> 0 | L25: =E25*INDEX('Price List'!$O$3:$O$20,MATCH($C25,'Price List'!$C$3:$C$20,0)) -> 2 | M25: =E25*INDEX('Price List'!$P$3:$P$20,MATCH($C25,'Price List'!$C$3:$C$20,0)) -> 0 | N25: =E25*INDEX('Price List'!$Q$3:$Q$20,MATCH($C25,'Price List'!$C$3:$C$20,0)) -> 0 | O25: =IF(LEFT(C25,3)="TM3",E25,0) -> 1 | Q25: =E25*INDEX(요약!$C$4:$C$7,MATCH($A25,요약!$A$4:$A$7,0)) -> 300
A26: ANU | B26: C | C26: 소계 | D26: 안C: AC220V CPU + Relay (MCC는 DC24V Relay) | G26: =SUM(G24:G25) -> 544750 | H26: =SUM(H24:H25) -> 24 | I26: =SUM(I24:I25) -> 4 | J26: =SUM(J24:J25) -> 12 | K26: =SUM(K24:K25) -> 16 | L26: =SUM(L24:L25) -> 2 | M26: =SUM(M24:M25) -> 2 | N26: =SUM(N24:N25) -> 0 | O26: =SUM(O24:O25) -> 1 | P26: =IF(AND(H26>=H16,K26>=K16,TRUE(),L26>=L16,M26>=M16,N26>=N16),IF(O26>7,"OK (TM3 버스확장 필요)","OK"),"사양 미달") -> OK
A28: ANU-S | 기존: ABB PM564-RP
A29: ANU-S | B29: 요구 사양 | D29: 기존 사양표 기준 요구 점수 | H29: 4 | K29: 6 | L29: 1 | M29: 2 | N29: 0
A30: ANU-S | B30: A | C30: TM241C24T | D30: CPU (PM564-RP 대체) | E30: 1 | F30: =INDEX('Price List'!$I$3:$I$20,MATCH($C30,'Price List'!$C$3:$C$20,0)) -> 392850 | G30: =E30*F30 -> 392850 | H30: =E30*INDEX('Price List'!$K$3:$K$20,MATCH($C30,'Price List'!$C$3:$C$20,0)) -> 14 | I30: =E30*INDEX('Price List'!$L$3:$L$20,MATCH($C30,'Price List'!$C$3:$C$20,0)) -> 10 | J30: =E30*INDEX('Price List'!$M$3:$M$20,MATCH($C30,'Price List'!$C$3:$C$20,0)) -> 0 | K30: =I30+J30 -> 10 | L30: =E30*INDEX('Price List'!$O$3:$O$20,MATCH($C30,'Price List'!$C$3:$C$20,0)) -> 0 | M30: =E30*INDEX('Price List'!$P$3:$P$20,MATCH($C30,'Price List'!$C$3:$C$20,0)) -> 2 | N30: =E30*INDEX('Price List'!$Q$3:$Q$20,MATCH($C30,'Price List'!$C$3:$C$20,0)) -> 0 | O30: =IF(LEFT(C30,3)="TM3",E30,0) -> 0 | Q30: =E30*INDEX(요약!$C$4:$C$7,MATCH($A30,요약!$A$4:$A$7,0)) -> 50
A31: ANU-S | B31: A | C31: TM3DQ8R | D31: Relay DO8 | E31: 1 | F31: =INDEX('Price List'!$I$3:$I$20,MATCH($C31,'Price List'!$C$3:$C$20,0)) -> 64400 | G31: =E31*F31 -> 64400 | H31: =E31*INDEX('Price List'!$K$3:$K$20,MATCH($C31,'Price List'!$C$3:$C$20,0)) -> 0 | I31: =E31*INDEX('Price List'!$L$3:$L$20,MATCH($C31,'Price List'!$C$3:$C$20,0)) -> 0 | J31: =E31*INDEX('Price List'!$M$3:$M$20,MATCH($C31,'Price List'!$C$3:$C$20,0)) -> 8 | K31: =I31+J31 -> 8 | L31: =E31*INDEX('Price List'!$O$3:$O$20,MATCH($C31,'Price List'!$C$3:$C$20,0)) -> 0 | M31: =E31*INDEX('Price List'!$P$3:$P$20,MATCH($C31,'Price List'!$C$3:$C$20,0)) -> 0 | N31: =E31*INDEX('Price List'!$Q$3:$Q$20,MATCH($C31,'Price List'!$C$3:$C$20,0)) -> 0 | O31: =IF(LEFT(C31,3)="TM3",E31,0) -> 1 | Q31: =E31*INDEX(요약!$C$4:$C$7,MATCH($A31,요약!$A$4:$A$7,0)) -> 50
A32: ANU-S | B32: A | C32: TM3AQ2 | D32: AO (PM564 내장 AO1 대체) | E32: 1 | F32: =INDEX('Price List'!$I$3:$I$20,MATCH($C32,'Price List'!$C$3:$C$20,0)) -> 138400 | G32: =E32*F32 -> 138400 | H32: =E32*INDEX('Price List'!$K$3:$K$20,MATCH($C32,'Price List'!$C$3:$C$20,0)) -> 0 | I32: =E32*INDEX('Price List'!$L$3:$L$20,MATCH($C32,'Price List'!$C$3:$C$20,0)) -> 0 | J32: =E32*INDEX('Price List'!$M$3:$M$20,MATCH($C32,'Price List'!$C$3:$C$20,0)) -> 0 | K32: =I32+J32 -> 0 | L32: =E32*INDEX('Price List'!$O$3:$O$20,MATCH($C32,'Price List'!$C$3:$C$20,0)) -> 2 | M32: =E32*INDEX('Price List'!$P$3:$P$20,MATCH($C32,'Price List'!$C$3:$C$20,0)) -> 0 | N32: =E32*INDEX('Price List'!$Q$3:$Q$20,MATCH($C32,'Price List'!$C$3:$C$20,0)) -> 0 | O32: =IF(LEFT(C32,3)="TM3",E32,0) -> 1 | Q32: =E32*INDEX(요약!$C$4:$C$7,MATCH($A32,요약!$A$4:$A$7,0)) -> 50
A33: ANU-S | B33: A | C33: 소계 | D33: 안A: 24VDC + Relay 출력 (기존 ABB와 동일 방식) | G33: =SUM(G30:G32) -> 595650 | H33: =SUM(H30:H32) -> 14 | I33: =SUM(I30:I32) -> 10 | J33: =SUM(J30:J32) -> 8 | K33: =SUM(K30:K32) -> 18 | L33: =SUM(L30:L32) -> 2 | M33: =SUM(M30:M32) -> 2 | N33: =SUM(N30:N32) -> 0 | O33: =SUM(O30:O32) -> 2 | P33: =IF(AND(H33>=H29,K33>=K29,J33>=K29,L33>=L29,M33>=M29,N33>=N29),IF(O33>7,"OK (TM3 버스확장 필요)","OK"),"사양 미달") -> OK
A34: ANU-S | B34: B | C34: TM241C24T | D34: CPU, Tr DO10 (PM564-RP 대체) | E34: 1 | F34: =INDEX('Price List'!$I$3:$I$20,MATCH($C34,'Price List'!$C$3:$C$20,0)) -> 392850 | G34: =E34*F34 -> 392850 | H34: =E34*INDEX('Price List'!$K$3:$K$20,MATCH($C34,'Price List'!$C$3:$C$20,0)) -> 14 | I34: =E34*INDEX('Price List'!$L$3:$L$20,MATCH($C34,'Price List'!$C$3:$C$20,0)) -> 10 | J34: =E34*INDEX('Price List'!$M$3:$M$20,MATCH($C34,'Price List'!$C$3:$C$20,0)) -> 0 | K34: =I34+J34 -> 10 | L34: =E34*INDEX('Price List'!$O$3:$O$20,MATCH($C34,'Price List'!$C$3:$C$20,0)) -> 0 | M34: =E34*INDEX('Price List'!$P$3:$P$20,MATCH($C34,'Price List'!$C$3:$C$20,0)) -> 2 | N34: =E34*INDEX('Price List'!$Q$3:$Q$20,MATCH($C34,'Price List'!$C$3:$C$20,0)) -> 0 | O34: =IF(LEFT(C34,3)="TM3",E34,0) -> 0 | Q34: =E34*INDEX(요약!$C$4:$C$7,MATCH($A34,요약!$A$4:$A$7,0)) -> 50
A35: ANU-S | B35: B | C35: TM3AQ2 | D35: AO (PM564 내장 AO1 대체) | E35: 1 | F35: =INDEX('Price List'!$I$3:$I$20,MATCH($C35,'Price List'!$C$3:$C$20,0)) -> 138400 | G35: =E35*F35 -> 138400 | H35: =E35*INDEX('Price List'!$K$3:$K$20,MATCH($C35,'Price List'!$C$3:$C$20,0)) -> 0 | I35: =E35*INDEX('Price List'!$L$3:$L$20,MATCH($C35,'Price List'!$C$3:$C$20,0)) -> 0 | J35: =E35*INDEX('Price List'!$M$3:$M$20,MATCH($C35,'Price List'!$C$3:$C$20,0)) -> 0 | K35: =I35+J35 -> 0 | L35: =E35*INDEX('Price List'!$O$3:$O$20,MATCH($C35,'Price List'!$C$3:$C$20,0)) -> 2 | M35: =E35*INDEX('Price List'!$P$3:$P$20,MATCH($C35,'Price List'!$C$3:$C$20,0)) -> 0 | N35: =E35*INDEX('Price List'!$Q$3:$Q$20,MATCH($C35,'Price List'!$C$3:$C$20,0)) -> 0 | O35: =IF(LEFT(C35,3)="TM3",E35,0) -> 1 | Q35: =E35*INDEX(요약!$C$4:$C$7,MATCH($A35,요약!$A$4:$A$7,0)) -> 50
A36: ANU-S | B36: B | C36: 소계 | D36: 안B: DC24V 최저가 (TSU/ANU/ANU-S Tr, MCC Relay) | G36: =SUM(G34:G35) -> 531250 | H36: =SUM(H34:H35) -> 14 | I36: =SUM(I34:I35) -> 10 | J36: =SUM(J34:J35) -> 0 | K36: =SUM(K34:K35) -> 10 | L36: =SUM(L34:L35) -> 2 | M36: =SUM(M34:M35) -> 2 | N36: =SUM(N34:N35) -> 0 | O36: =SUM(O34:O35) -> 1 | P36: =IF(AND(H36>=H29,K36>=K29,TRUE(),L36>=L29,M36>=M29,N36>=N29),IF(O36>7,"OK (TM3 버스확장 필요)","OK"),"사양 미달") -> OK
A37: ANU-S | B37: C | C37: TM241C24R | D37: CPU, Relay DO6 + Tr4 (PM564-RP 대체) | E37: 1 | F37: =INDEX('Price List'!$I$3:$I$20,MATCH($C37,'Price List'!$C$3:$C$20,0)) -> 384750 | G37: =E37*F37 -> 384750 | H37: =E37*INDEX('Price List'!$K$3:$K$20,MATCH($C37,'Price List'!$C$3:$C$20,0)) -> 14 | I37: =E37*INDEX('Price List'!$L$3:$L$20,MATCH($C37,'Price List'!$C$3:$C$20,0)) -> 4 | J37: =E37*INDEX('Price List'!$M$3:$M$20,MATCH($C37,'Price List'!$C$3:$C$20,0)) -> 6 | K37: =I37+J37 -> 10 | L37: =E37*INDEX('Price List'!$O$3:$O$20,MATCH($C37,'Price List'!$C$3:$C$20,0)) -> 0 | M37: =E37*INDEX('Price List'!$P$3:$P$20,MATCH($C37,'Price List'!$C$3:$C$20,0)) -> 2 | N37: =E37*INDEX('Price List'!$Q$3:$Q$20,MATCH($C37,'Price List'!$C$3:$C$20,0)) -> 0 | O37: =IF(LEFT(C37,3)="TM3",E37,0) -> 0 | Q37: =E37*INDEX(요약!$C$4:$C$7,MATCH($A37,요약!$A$4:$A$7,0)) -> 50
A38: ANU-S | B38: C | C38: TM3AQ2 | D38: AO (PM564 내장 AO1 대체) | E38: 1 | F38: =INDEX('Price List'!$I$3:$I$20,MATCH($C38,'Price List'!$C$3:$C$20,0)) -> 138400 | G38: =E38*F38 -> 138400 | H38: =E38*INDEX('Price List'!$K$3:$K$20,MATCH($C38,'Price List'!$C$3:$C$20,0)) -> 0 | I38: =E38*INDEX('Price List'!$L$3:$L$20,MATCH($C38,'Price List'!$C$3:$C$20,0)) -> 0 | J38: =E38*INDEX('Price List'!$M$3:$M$20,MATCH($C38,'Price List'!$C$3:$C$20,0)) -> 0 | K38: =I38+J38 -> 0 | L38: =E38*INDEX('Price List'!$O$3:$O$20,MATCH($C38,'Price List'!$C$3:$C$20,0)) -> 2 | M38: =E38*INDEX('Price List'!$P$3:$P$20,MATCH($C38,'Price List'!$C$3:$C$20,0)) -> 0 | N38: =E38*INDEX('Price List'!$Q$3:$Q$20,MATCH($C38,'Price List'!$C$3:$C$20,0)) -> 0 | O38: =IF(LEFT(C38,3)="TM3",E38,0) -> 1 | Q38: =E38*INDEX(요약!$C$4:$C$7,MATCH($A38,요약!$A$4:$A$7,0)) -> 50
A39: ANU-S | B39: C | C39: 소계 | D39: 안C: AC220V CPU + Relay (MCC는 DC24V Relay) | G39: =SUM(G37:G38) -> 523150 | H39: =SUM(H37:H38) -> 14 | I39: =SUM(I37:I38) -> 4 | J39: =SUM(J37:J38) -> 6 | K39: =SUM(K37:K38) -> 10 | L39: =SUM(L37:L38) -> 2 | M39: =SUM(M37:M38) -> 2 | N39: =SUM(N37:N38) -> 0 | O39: =SUM(O37:O38) -> 1 | P39: =IF(AND(H39>=H29,K39>=K29,TRUE(),L39>=L29,M39>=M29,N39>=N29),IF(O39>7,"OK (TM3 버스확장 필요)","OK"),"사양 미달") -> OK
A41: MCC | 기존: ABB PM564-RP-ETH + DI562×6 + DO573×3 + AO561×2
A42: MCC | B42: 요구 사양 | D42: 현행 유지: DI 6+16×6, DO 6+16×3, AO 2×2 | H42: 102 | K42: 54 | L42: 4 | M42: 1 | N42: 1
A43: MCC | B43: A | C43: TM241CE24T | D43: CPU + Ethernet (PM564-RP-ETH 대체) | E43: 1 | F43: =INDEX('Price List'!$I$3:$I$20,MATCH($C43,'Price List'!$C$3:$C$20,0)) -> 398700 | G43: =E43*F43 -> 398700 | H43: =E43*INDEX('Price List'!$K$3:$K$20,MATCH($C43,'Price List'!$C$3:$C$20,0)) -> 14 | I43: =E43*INDEX('Price List'!$L$3:$L$20,MATCH($C43,'Price List'!$C$3:$C$20,0)) -> 10 | J43: =E43*INDEX('Price List'!$M$3:$M$20,MATCH($C43,'Price List'!$C$3:$C$20,0)) -> 0 | K43: =I43+J43 -> 10 | L43: =E43*INDEX('Price List'!$O$3:$O$20,MATCH($C43,'Price List'!$C$3:$C$20,0)) -> 0 | M43: =E43*INDEX('Price List'!$P$3:$P$20,MATCH($C43,'Price List'!$C$3:$C$20,0)) -> 2 | N43: =E43*INDEX('Price List'!$Q$3:$Q$20,MATCH($C43,'Price List'!$C$3:$C$20,0)) -> 1 | O43: =IF(LEFT(C43,3)="TM3",E43,0) -> 0 | Q43: =E43*INDEX(요약!$C$4:$C$7,MATCH($A43,요약!$A$4:$A$7,0)) -> 100
A44: MCC | B44: A | C44: TM3DI16 | D44: DI16 ×6 (DI562×6 대체) | E44: 6 | F44: =INDEX('Price List'!$I$3:$I$20,MATCH($C44,'Price List'!$C$3:$C$20,0)) -> 91200 | G44: =E44*F44 -> 547200 | H44: =E44*INDEX('Price List'!$K$3:$K$20,MATCH($C44,'Price List'!$C$3:$C$20,0)) -> 96 | I44: =E44*INDEX('Price List'!$L$3:$L$20,MATCH($C44,'Price List'!$C$3:$C$20,0)) -> 0 | J44: =E44*INDEX('Price List'!$M$3:$M$20,MATCH($C44,'Price List'!$C$3:$C$20,0)) -> 0 | K44: =I44+J44 -> 0 | L44: =E44*INDEX('Price List'!$O$3:$O$20,MATCH($C44,'Price List'!$C$3:$C$20,0)) -> 0 | M44: =E44*INDEX('Price List'!$P$3:$P$20,MATCH($C44,'Price List'!$C$3:$C$20,0)) -> 0 | N44: =E44*INDEX('Price List'!$Q$3:$Q$20,MATCH($C44,'Price List'!$C$3:$C$20,0)) -> 0 | O44: =IF(LEFT(C44,3)="TM3",E44,0) -> 6 | Q44: =E44*INDEX(요약!$C$4:$C$7,MATCH($A44,요약!$A$4:$A$7,0)) -> 600
...

Sheet 연간 BOM
A1: 모듈별 연간 소요량 (BOM) — 구성안별
A2: 연간 수량 = Σ(시스템별 1 set 수량 × 시스템 연간 구매수량). 수량 기반 추가 할인 협상용. 단가는 현재 특가.
A3: Material | B3: 비고 | C3: 특가 단가 | D3: 안A | F3: 안B | H3: 안C
D4: 연간 수량 | E4: 연간 금액 | F4: 연간 수량 | G4: 연간 금액 | H4: 연간 수량 | I4: 연간 금액
A5: ='Price List'!C3 -> TM241CE24T | B5: ='Price List'!R3 -> CPU, Ethernet, 24VDC | C5: ='Price List'!I3 -> 398700 | D5: =SUMIFS('기준사양 매칭'!$Q$5:$Q$200,'기준사양 매칭'!$C$5:$C$200,$A5,'기준사양 매칭'!$B$5:$B$200,"A") -> 100 | E5: =D5*$C5 -> 39870000 | F5: =SUMIFS('기준사양 매칭'!$Q$5:$Q$200,'기준사양 매칭'!$C$5:$C$200,$A5,'기준사양 매칭'!$B$5:$B$200,"B") -> 100 | G5: =F5*$C5 -> 39870000 | H5: =SUMIFS('기준사양 매칭'!$Q$5:$Q$200,'기준사양 매칭'!$C$5:$C$200,$A5,'기준사양 매칭'!$B$5:$B$200,"C") -> 100 | I5: =H5*$C5 -> 39870000
A6: ='Price List'!C4 -> TM241C24T | B6: ='Price List'!R4 -> CPU, 24VDC | C6: ='Price List'!I4 -> 392850 | D6: =SUMIFS('기준사양 매칭'!$Q$5:$Q$200,'기준사양 매칭'!$C$5:$C$200,$A6,'기준사양 매칭'!$B$5:$B$200,"A") -> 550 | E6: =D6*$C6 -> 216067500 | F6: =SUMIFS('기준사양 매칭'!$Q$5:$Q$200,'기준사양 매칭'!$C$5:$C$200,$A6,'기준사양 매칭'!$B$5:$B$200,"B") -> 250 | G6: =F6*$C6 -> 98212500 | H6: =SUMIFS('기준사양 매칭'!$Q$5:$Q$200,'기준사양 매칭'!$C$5:$C$200,$A6,'기준사양 매칭'!$B$5:$B$200,"C") -> 0 | I6: =H6*$C6 -> 0
A7: ='Price List'!C5 -> TM241C24R | B7: ='Price List'!R5 -> CPU, 100-240VAC | C7: ='Price List'!I5 -> 384750 | D7: =SUMIFS('기준사양 매칭'!$Q$5:$Q$200,'기준사양 매칭'!$C$5:$C$200,$A7,'기준사양 매칭'!$B$5:$B$200,"A") -> 0 | E7: =D7*$C7 -> 0 | F7: =SUMIFS('기준사양 매칭'!$Q$5:$Q$200,'기준사양 매칭'!$C$5:$C$200,$A7,'기준사양 매칭'!$B$5:$B$200,"B") -> 0 | G7: =F7*$C7 -> 0 | H7: =SUMIFS('기준사양 매칭'!$Q$5:$Q$200,'기준사양 매칭'!$C$5:$C$200,$A7,'기준사양 매칭'!$B$5:$B$200,"C") -> 250 | I7: =H7*$C7 -> 96187500
A8: ='Price List'!C6 -> TM241C40T | B8: ='Price List'!R6 -> CPU, 24VDC | C8: ='Price List'!I6 -> 417600 | D8: =SUMIFS('기준사양 매칭'!$Q$5:$Q$200,'기준사양 매칭'!$C$5:$C$200,$A8,'기준사양 매칭'!$B$5:$B$200,"A") -> 0 | E8: =D8*$C8 -> 0 | F8: =SUMIFS('기준사양 매칭'!$Q$5:$Q$200,'기준사양 매칭'!$C$5:$C$200,$A8,'기준사양 매칭'!$B$5:$B$200,"B") -> 300 | G8: =F8*$C8 -> 125280000 | H8: =SUMIFS('기준사양 매칭'!$Q$5:$Q$200,'기준사양 매칭'!$C$5:$C$200,$A8,'기준사양 매칭'!$B$5:$B$200,"C") -> 0 | I8: =H8*$C8 -> 0
A9: ='Price List'!C7 -> TM241C40R | B9: ='Price List'!R7 -> CPU, 100-240VAC | C9: ='Price List'!I7 -> 406350 | D9: =SUMIFS('기준사양 매칭'!$Q$5:$Q$200,'기준사양 매칭'!$C$5:$C$200,$A9,'기준사양 매칭'!$B$5:$B$200,"A") -> 0 | E9: =D9*$C9 -> 0 | F9: =SUMIFS('기준사양 매칭'!$Q$5:$Q$200,'기준사양 매칭'!$C$5:$C$200,$A9,'기준사양 매칭'!$B$5:$B$200,"B") -> 0 | G9: =F9*$C9 -> 0 | H9: =SUMIFS('기준사양 매칭'!$Q$5:$Q$200,'기준사양 매칭'!$C$5:$C$200,$A9,'기준사양 매칭'!$B$5:$B$200,"C") -> 300 | I9: =H9*$C9 -> 121905000
A10: ='Price List'!C8 -> TM3DI16 | B10: ='Price List'!R8 -> DI 16 | C10: ='Price List'!I8 -> 91200 | D10: =SUMIFS('기준사양 매칭'!$Q$5:$Q$200,'기준사양 매칭'!$C$5:$C$200,$A10,'기준사양 매칭'!$B$5:$B$200,"A") -> 600 | E10: =D10*$C10 -> 54720000 | F10: =SUMIFS('기준사양 매칭'!$Q$5:$Q$200,'기준사양 매칭'!$C$5:$C$200,$A10,'기준사양 매칭'!$B$5:$B$200,"B") -> 600 | G10: =F10*$C10 -> 54720000 | H10: =SUMIFS('기준사양 매칭'!$Q$5:$Q$200,'기준사양 매칭'!$C$5:$C$200,$A10,'기준사양 매칭'!$B$5:$B$200,"C") -> 600 | I10: =H10*$C10 -> 54720000
A11: ='Price List'!C9 -> TM3DI8 | B11: ='Price List'!R9 -> DI 8 | C11: ='Price List'!I9 -> 80800 | D11: =SUMIFS('기준사양 매칭'!$Q$5:$Q$200,'기준사양 매칭'!$C$5:$C$200,$A11,'기준사양 매칭'!$B$5:$B$200,"A") -> 0 | E11: =D11*$C11 -> 0 | F11: =SUMIFS('기준사양 매칭'!$Q$5:$Q$200,'기준사양 매칭'!$C$5:$C$200,$A11,'기준사양 매칭'!$B$5:$B$200,"B") -> 0 | G11: =F11*$C11 -> 0 | H11: =SUMIFS('기준사양 매칭'!$Q$5:$Q$200,'기준사양 매칭'!$C$5:$C$200,$A11,'기준사양 매칭'!$B$5:$B$200,"C") -> 0 | I11: =H11*$C11 -> 0
A12: ='Price List'!C10 -> TM3DQ16R | B12: ='Price List'!R10 -> DO 16 Relay | C12: ='Price List'!I10 -> 90800 | D12: =SUMIFS('기준사양 매칭'!$Q$5:$Q$200,'기준사양 매칭'!$C$5:$C$200,$A12,'기준사양 매칭'!$B$5:$B$200,"A") -> 700 | E12: =D12*$C12 -> 63560000 | F12: =SUMIFS('기준사양 매칭'!$Q$5:$Q$200,'기준사양 매칭'!$C$5:$C$200,$A12,'기준사양 매칭'!$B$5:$B$200,"B") -> 400 | G12: =F12*$C12 -> 36320000 | H12: =SUMIFS('기준사양 매칭'!$Q$5:$Q$200,'기준사양 매칭'!$C$5:$C$200,$A12,'기준사양 매칭'!$B$5:$B$200,"C") -> 400 | I12: =H12*$C12 -> 36320000
A13: ='Price List'!C11 -> TM3DQ16T | B13: ='Price List'!R11 -> DO 16 Tr (Source) | C13: ='Price List'!I11 -> 90800 | D13: =SUMIFS('기준사양 매칭'!$Q$5:$Q$200,'기준사양 매칭'!$C$5:$C$200,$A13,'기준사양 매칭'!$B$5:$B$200,"A") -> 0 | E13: =D13*$C13 -> 0 | F13: =SUMIFS('기준사양 매칭'!$Q$5:$Q$200,'기준사양 매칭'!$C$5:$C$200,$A13,'기준사양 매칭'!$B$5:$B$200,"B") -> 0 | G13: =F13*$C13 -> 0 | H13: =SUMIFS('기준사양 매칭'!$Q$5:$Q$200,'기준사양 매칭'!$C$5:$C$200,$A13,'기준사양 매칭'!$B$5:$B$200,"C") -> 0 | I13: =H13*$C13 -> 0
A14: ='Price List'!C12 -> TM3DQ16U | B14: ='Price List'!R12 -> DO 16 Tr (Sink) | C14: ='Price List'!I12 -> 85200 | D14: =SUMIFS('기준사양 매칭'!$Q$5:$Q$200,'기준사양 매칭'!$C$5:$C$200,$A14,'기준사양 매칭'!$B$5:$B$200,"A") -> 0 | E14: =D14*$C14 -> 0 | F14: =SUMIFS('기준사양 매칭'!$Q$5:$Q$200,'기준사양 매칭'!$C$5:$C$200,$A14,'기준사양 매칭'!$B$5:$B$200,"B") -> 0 | G14: =F14*$C14 -> 0 | H14: =SUMIFS('기준사양 매칭'!$Q$5:$Q$200,'기준사양 매칭'!$C$5:$C$200,$A14,'기준사양 매칭'!$B$5:$B$200,"C") -> 0 | I14: =H14*$C14 -> 0
A15: ='Price List'!C13 -> TM3DQ8R | B15: ='Price List'!R13 -> DO 8 Relay | C15: ='Price List'!I13 -> 64400 | D15: =SUMIFS('기준사양 매칭'!$Q$5:$Q$200,'기준사양 매칭'!$C$5:$C$200,$A15,'기준사양 매칭'!$B$5:$B$200,"A") -> 250 | E15: =D15*$C15 -> 16100000 | F15: =SUMIFS('기준사양 매칭'!$Q$5:$Q$200,'기준사양 매칭'!$C$5:$C$200,$A15,'기준사양 매칭'!$B$5:$B$200,"B") -> 0 | G15: =F15*$C15 -> 0 | H15: =SUMIFS('기준사양 매칭'!$Q$5:$Q$200,'기준사양 매칭'!$C$5:$C$200,$A15,'기준사양 매칭'!$B$5:$B$200,"C") -> 0 | I15: =H15*$C15 -> 0
A16: ='Price List'!C14 -> TM3DQ8T | B16: ='Price List'!R14 -> DO 8 Tr (Source) | C16: ='Price List'!I14 -> 67200 | D16: =SUMIFS('기준사양 매칭'!$Q$5:$Q$200,'기준사양 매칭'!$C$5:$C$200,$A16,'기준사양 매칭'!$B$5:$B$200,"A") -> 0 | E16: =D16*$C16 -> 0 | F16: =SUMIFS('기준사양 매칭'!$Q$5:$Q$200,'기준사양 매칭'!$C$5:$C$200,$A16,'기준사양 매칭'!$B$5:$B$200,"B") -> 0 | G16: =F16*$C16 -> 0 | H16: =SUMIFS('기준사양 매칭'!$Q$5:$Q$200,'기준사양 매칭'!$C$5:$C$200,$A16,'기준사양 매칭'!$B$5:$B$200,"C") -> 0 | I16: =H16*$C16 -> 0
... A22: ='Price List'!C20 -> TM3AQ4 | B22: ='Price List'!R20 -> AO 4 | C22: ='Price List'!I20 -> 140400 | D22: =SUMIFS('기준사양 매칭'!$Q$5:$Q$200,'기준사양 매칭'!$C$5:$C$200,$A22,'기준사양 매칭'!$B$5:$B$200,"A") -> 100 | E22: =D22*$C22 -> 14040000 | F22: =SUMIFS('기준사양 매칭'!$Q$5:$Q$200,'기준사양 매칭'!$C$5:$C$200,$A22,'기준사양 매칭'!$B$5:$B$200,"B") -> 100 | G22: =F22*$C22 -> 14040000 | H22: =SUMIFS('기준사양 매칭'!$Q$5:$Q$200,'기준사양 매칭'!$C$5:$C$200,$A22,'기준사양 매칭'!$B$5:$B$200,"C") -> 100 | I22: =H22*$C22 -> 14040000
A23: 합계 | D23: =SUM(D5:D22) -> 2650 | E23: =SUM(E5:E22) -> 452797500 | F23: =SUM(F5:F22) -> 2100 | G23: =SUM(G5:G22) -> 416882500 | H23: =SUM(H5:H22) -> 2100 | I23: =SUM(I5:I22) -> 411482500
A24: 검증: '요약' 연간 금액과 일치 여부 | E24: =IF(ABS(E23-요약!G8)<1,"일치","불일치") -> 일치 | G24: =IF(ABS(G23-요약!H8)<1,"일치","불일치") -> 일치 | I24: =IF(ABS(I23-요약!I8)<1,"일치","불일치") -> 일치

Sheet Schneider 제안 검토
A1: Schneider 제안 검토 — RFQ 'PLC 사양서 R3.1' 대비
A2: Schneider 제안 구성(PLC Configuration for Techross R3.1 / Table1)을 'Price List' 특가로 산정하고, RFQ 요구(필수 점수 +10% Spare, MCC Relay Only)와 비교. 요구 점수는 '기준사양 매칭' 시트, 연간 수량은 '요약' 시트 참조.
A4: 가격표 미포함 품목 | B4: List Price (추정) | C4: DF | D4: 특가 단가 | E4: DI | F4: DO (Tr) | G4: Serial | H4: Ethernet | I4: 근거
A5: TM241CE40T | B5: 941000 | C5: 0.45 | D5: =ROUND(B5*C5,0) -> 423450 | E5: 24 | F5: 16 | G5: 2 | H5: 1 | I5: 추정: TM241C40T 정가 928,000 + (CE24T−C24T 정가차 13,000), CPU DF 0.45 — 실견적 받으면 B5에 입력
A7: 시스템 | B7: 전원 | C7: Reference | D7: Q'ty | E7: 특가 단가 | F7: 금액 (1 set) | G7: DI | H7: DO 합계 | I7: DO 중 Relay | J7: AO | K7: Serial | L7: Ethernet | M7: 연간 수량 | N7: 연간 금액 | O7: 판정 (요구 점수 대비)
A8: TSU | B8: AC220V | C8: TM241C24R | D8: 1 | E8: =IFERROR(INDEX('Price List'!$I$3:$I$20,MATCH($C8,'Price List'!$C$3:$C$20,0)),IFERROR(INDEX($D$5:$D$5,MATCH($C8,$A$5:$A$5,0)),0)) -> 384750 | F8: =D8*E8 -> 384750 | G8: =D8*IFERROR(INDEX('Price List'!$K$3:$K$20,MATCH($C8,'Price List'!$C$3:$C$20,0)),IFERROR(INDEX($E$5:$E$5,MATCH($C8,$A$5:$A$5,0)),0)) -> 14 | H8: =D8*(IFERROR(INDEX('Price List'!$L$3:$L$20,MATCH($C8,'Price List'!$C$3:$C$20,0)),IFERROR(INDEX($F$5:$F$5,MATCH($C8,$A$5:$A$5,0)),0))+IFERROR(INDEX('Price List'!$M$3:$M$20,MATCH($C8,'Price List'!$C$3:$C$20,0)),0)) -> 10 | I8: =D8*IFERROR(INDEX('Price List'!$M$3:$M$20,MATCH($C8,'Price List'!$C$3:$C$20,0)),0) -> 6 | J8: =D8*IFERROR(INDEX('Price List'!$O$3:$O$20,MATCH($C8,'Price List'!$C$3:$C$20,0)),0) -> 0 | K8: =D8*IFERROR(INDEX('Price List'!$P$3:$P$20,MATCH($C8,'Price List'!$C$3:$C$20,0)),IFERROR(INDEX($G$5:$G$5,MATCH($C8,$A$5:$A$5,0)),0)) -> 2 | L8: =D8*IFERROR(INDEX('Price List'!$Q$3:$Q$20,MATCH($C8,'Price List'!$C$3:$C$20,0)),IFERROR(INDEX($H$5:$H$5,MATCH($C8,$A$5:$A$5,0)),0)) -> 0
A9: TSU | B9: AC220V | C9: 소계 | F9: =SUM(F8:F8) -> 384750 | G9: =SUM(G8:G8) -> 14 | H9: =SUM(H8:H8) -> 10 | I9: =SUM(I8:I8) -> 6 | J9: =SUM(J8:J8) -> 0 | K9: =SUM(K8:K8) -> 2 | L9: =SUM(L8:L8) -> 0 | M9: =INDEX(요약!$C$4:$C$7,MATCH($A9,요약!$A$4:$A$7,0)) -> 200 | N9: =F9*M9 -> 76950000 | O9: =IF(AND(G9>='기준사양 매칭'!H6,H9>='기준사양 매칭'!K6,J9>='기준사양 매칭'!L6,K9>='기준사양 매칭'!M6,L9>='기준사양 매칭'!N6),"충족",IF(G9<'기준사양 매칭'!H6,"DI "&('기준사양 매칭'!H6-G9)&" 부족 ","")&IF(H9<'기준사양 매칭'!K6,"DO "&('기준사양 매칭'!K6-H9)&" 부족 ","")&IF(J9<'기준사양 매칭'!L6,"AO "&('기준사양 매칭'!L6-J9)&" 부족 ","")&IF(K9<'기준사양 매칭'!M6,"Serial "&('기준사양 매칭'!M6-K9)&" 부족 ","")&IF(L9<'기준사양 매칭'!N6,"ETH "&('기준사양 매칭'!N6-L9)&" 부족 ","")) -> 충족
A11: TSU | B11: DC24V | C11: TM241C24T | D11: 1 | E11: =IFERROR(INDEX('Price List'!$I$3:$I$20,MATCH($C11,'Price List'!$C$3:$C$20,0)),IFERROR(INDEX($D$5:$D$5,MATCH($C11,$A$5:$A$5,0)),0)) -> 392850 | F11: =D11*E11 -> 392850 | G11: =D11*IFERROR(INDEX('Price List'!$K$3:$K$20,MATCH($C11,'Price List'!$C$3:$C$20,0)),IFERROR(INDEX($E$5:$E$5,MATCH($C11,$A$5:$A$5,0)),0)) -> 14 | H11: =D11*(IFERROR(INDEX('Price List'!$L$3:$L$20,MATCH($C11,'Price List'!$C$3:$C$20,0)),IFERROR(INDEX($F$5:$F$5,MATCH($C11,$A$5:$A$5,0)),0))+IFERROR(INDEX('Price List'!$M$3:$M$20,MATCH($C11,'Price List'!$C$3:$C$20,0)),0)) -> 10 | I11: =D11*IFERROR(INDEX('Price List'!$M$3:$M$20,MATCH($C11,'Price List'!$C$3:$C$20,0)),0) -> 0 | J11: =D11*IFERROR(INDEX('Price List'!$O$3:$O$20,MATCH($C11,'Price List'!$C$3:$C$20,0)),0) -> 0 | K11: =D11*IFERROR(INDEX('Price List'!$P$3:$P$20,MATCH($C11,'Price List'!$C$3:$C$20,0)),IFERROR(INDEX($G$5:$G$5,MATCH($C11,$A$5:$A$5,0)),0)) -> 2 | L11: =D11*IFERROR(INDEX('Price List'!$Q$3:$Q$20,MATCH($C11,'Price List'!$C$3:$C$20,0)),IFERROR(INDEX($H$5:$H$5,MATCH($C11,$A$5:$A$5,0)),0)) -> 0
A12: TSU | B12: DC24V | C12: 소계 | F12: =SUM(F11:F11) -> 392850 | G12: =SUM(G11:G11) -> 14 | H12: =SUM(H11:H11) -> 10 | I12: =SUM(I11:I11) -> 0 | J12: =SUM(J11:J11) -> 0 | K12: =SUM(K11:K11) -> 2 | L12: =SUM(L11:L11) -> 0 | M12: =INDEX(요약!$C$4:$C$7,MATCH($A12,요약!$A$4:$A$7,0)) -> 200 | N12: =F12*M12 -> 78570000 | O12: =IF(AND(G12>='기준사양 매칭'!H6,H12>='기준사양 매칭'!K6,J12>='기준사양 매칭'!L6,K12>='기준사양 매칭'!M6,L12>='기준사양 매칭'!N6),"충족",IF(G12<'기준사양 매칭'!H6,"DI "&('기준사양 매칭'!H6-G12)&" 부족 ","")&IF(H12<'기준사양 매칭'!K6,"DO "&('기준사양 매칭'!K6-H12)&" 부족 ","")&IF(J12<'기준사양 매칭'!L6,"AO "&('기준사양 매칭'!L6-J12)&" 부족 ","")&IF(K12<'기준사양 매칭'!M6,"Serial "&('기준사양 매칭'!M6-K12)&" 부족 ","")&IF(L12<'기준사양 매칭'!N6,"ETH "&('기준사양 매칭'!N6-L12)&" 부족 ","")) -> 충족
A14: ANU | B14: AC220V | C14: TM241C40R | D14: 1 | E14: =IFERROR(INDEX('Price List'!$I$3:$I$20,MATCH($C14,'Price List'!$C$3:$C$20,0)),IFERROR(INDEX($D$5:$D$5,MATCH($C14,$A$5:$A$5,0)),0)) -> 406350 | F14: =D14*E14 -> 406350 | G14: =D14*IFERROR(INDEX('Price List'!$K$3:$K$20,MATCH($C14,'Price List'!$C$3:$C$20,0)),IFERROR(INDEX($E$5:$E$5,MATCH($C14,$A$5:$A$5,0)),0)) -> 24 | H14: =D14*(IFERROR(INDEX('Price List'!$L$3:$L$20,MATCH($C14,'Price List'!$C$3:$C$20,0)),IFERROR(INDEX($F$5:$F$5,MATCH($C14,$A$5:$A$5,0)),0))+IFERROR(INDEX('Price List'!$M$3:$M$20,MATCH($C14,'Price List'!$C$3:$C$20,0)),0)) -> 16 | I14: =D14*IFERROR(INDEX('Price List'!$M$3:$M$20,MATCH($C14,'Price List'!$C$3:$C$20,0)),0) -> 12 | J14: =D14*IFERROR(INDEX('Price List'!$O$3:$O$20,MATCH($C14,'Price List'!$C$3:$C$20,0)),0) -> 0 | K14: =D14*IFERROR(INDEX('Price List'!$P$3:$P$20,MATCH($C14,'Price List'!$C$3:$C$20,0)),IFERROR(INDEX($G$5:$G$5,MATCH($C14,$A$5:$A$5,0)),0)) -> 2 | L14: =D14*IFERROR(INDEX('Price List'!$Q$3:$Q$20,MATCH($C14,'Price List'!$C$3:$C$20,0)),IFERROR(INDEX($H$5:$H$5,MATCH($C14,$A$5:$A$5,0)),0)) -> 0
A15: ANU | B15: AC220V | C15: 소계 | F15: =SUM(F14:F14) -> 406350 | G15: =SUM(G14:G14) -> 24 | H15: =SUM(H14:H14) -> 16 | I15: =SUM(I14:I14) -> 12 | J15: =SUM(J14:J14) -> 0 | K15: =SUM(K14:K14) -> 2 | L15: =SUM(L14:L14) -> 0 | M15: =INDEX(요약!$C$4:$C$7,MATCH($A15,요약!$A$4:$A$7,0)) -> 300 | N15: =F15*M15 -> 121905000 | O15: =IF(AND(G15>='기준사양 매칭'!H16,H15>='기준사양 매칭'!K16,J15>='기준사양 매칭'!L16,K15>='기준사양 매칭'!M16,L15>='기준사양 매칭'!N16),"충족",IF(G15<'기준사양 매칭'!H16,"DI "&('기준사양 매칭'!H16-G15)&" 부족 ","")&IF(H15<'기준사양 매칭'!K16,"DO "&('기준사양 매칭'!K16-H15)&" 부족 ","")&IF(J15<'기준사양 매칭'!L16,"AO "&('기준사양 매칭'!L16-J15)&" 부족 ","")&IF(K15<'기준사양 매칭'!M16,"Serial "&('기준사양 매칭'!M16-K15)&" 부족 ","")&IF(L15<'기준사양 매칭'!N16,"ETH "&('기준사양 매칭'!N16-L15)&" 부족 ","")) -> AO 2 부족
A17: ANU | B17: DC24V | C17: TM241C40T | D17: 1 | E17: =IFERROR(INDEX('Price List'!$I$3:$I$20,MATCH($C17,'Price List'!$C$3:$C$20,0)),IFERROR(INDEX($D$5:$D$5,MATCH($C17,$A$5:$A$5,0)),0)) -> 417600 | F17: =D17*E17 -> 417600 | G17: =D17*IFERROR(INDEX('Price List'!$K$3:$K$20,MATCH($C17,'Price List'!$C$3:$C$20,0)),IFERROR(INDEX($E$5:$E$5,MATCH($C17,$A$5:$A$5,0)),0)) -> 24 | H17: =D17*(IFERROR(INDEX('Price List'!$L$3:$L$20,MATCH($C17,'Price List'!$C$3:$C$20,0)),IFERROR(INDEX($F$5:$F$5,MATCH($C17,$A$5:$A$5,0)),0))+IFERROR(INDEX('Price List'!$M$3:$M$20,MATCH($C17,'Price List'!$C$3:$C$20,0)),0)) -> 16 | I17: =D17*IFERROR(INDEX('Price List'!$M$3:$M$20,MATCH($C17,'Price List'!$C$3:$C$20,0)),0) -> 0 | J17: =D17*IFERROR(INDEX('Price List'!$O$3:$O$20,MATCH($C17,'Price List'!$C$3:$C$20,0)),0) -> 0 | K17: =D17*IFERROR(INDEX('Price List'!$P$3:$P$20,MATCH($C17,'Price List'!$C$3:$C$20,0)),IFERROR(INDEX($G$5:$G$5,MATCH($C17,$A$5:$A$5,0)),0)) -> 2 | L17: =D17*IFERROR(INDEX('Price List'!$Q$3:$Q$20,MATCH($C17,'Price List'!$C$3:$C$20,0)),IFERROR(INDEX($H$5:$H$5,MATCH($C17,$A$5:$A$5,0)),0)) -> 0
A18: ANU | B18: DC24V | C18: 소계 | F18: =SUM(F17:F17) -> 417600 | G18: =SUM(G17:G17) -> 24 | H18: =SUM(H17:H17) -> 16 | I18: =SUM(I17:I17) -> 0 | J18: =SUM(J17:J17) -> 0 | K18: =SUM(K17:K17) -> 2 | L18: =SUM(L17:L17) -> 0 | M18: =INDEX(요약!$C$4:$C$7,MATCH($A18,요약!$A$4:$A$7,0)) -> 300 | N18: =F18*M18 -> 125280000 | O18: =IF(AND(G18>='기준사양 매칭'!H16,H18>='기준사양 매칭'!K16,J18>='기준사양 매칭'!L16,K18>='기준사양 매칭'!M16,L18>='기준사양 매칭'!N16),"충족",IF(G18<'기준사양 매칭'!H16,"DI "&('기준사양 매칭'!H16-G18)&" 부족 ","")&IF(H18<'기준사양 매칭'!K16,"DO "&('기준사양 매칭'!K16-H18)&" 부족 ","")&IF(J18<'기준사양 매칭'!L16,"AO "&('기준사양 매칭'!L16-J18)&" 부족 ","")&IF(K18<'기준사양 매칭'!M16,"Serial "&('기준사양 매칭'!M16-K18)&" 부족 ","")&IF(L18<'기준사양 매칭'!N16,"ETH "&('기준사양 매칭'!N16-L18)&" 부족 ","")) -> AO 2 부족
A20: ANU-S | B20: AC220V | C20: TM241C24R | D20: 1 | E20: =IFERROR(INDEX('Price List'!$I$3:$I$20,MATCH($C20,'Price List'!$C$3:$C$20,0)),IFERROR(INDEX($D$5:$D$5,MATCH($C20,$A$5:$A$5,0)),0)) -> 384750 | F20: =D20*E20 -> 384750 | G20: =D20*IFERROR(INDEX('Price List'!$K$3:$K$20,MATCH($C20,'Price List'!$C$3:$C$20,0)),IFERROR(INDEX($E$5:$E$5,MATCH($C20,$A$5:$A$5,0)),0)) -> 14 | H20: =D20*(IFERROR(INDEX('Price List'!$L$3:$L$20,MATCH($C20,'Price List'!$C$3:$C$20,0)),IFERROR(INDEX($F$5:$F$5,MATCH($C20,$A$5:$A$5,0)),0))+IFERROR(INDEX('Price List'!$M$3:$M$20,MATCH($C20,'Price List'!$C$3:$C$20,0)),0)) -> 10 | I20: =D20*IFERROR(INDEX('Price List'!$M$3:$M$20,MATCH($C20,'Price List'!$C$3:$C$20,0)),0) -> 6 | J20: =D20*IFERROR(INDEX('Price List'!$O$3:$O$20,MATCH($C20,'Price List'!$C$3:$C$20,0)),0) -> 0 | K20: =D20*IFERROR(INDEX('Price List'!$P$3:$P$20,MATCH($C20,'Price List'!$C$3:$C$20,0)),IFERROR(INDEX($G$5:$G$5,MATCH($C20,$A$5:$A$5,0)),0)) -> 2 | L20: =D20*IFERROR(INDEX('Price List'!$Q$3:$Q$20,MATCH($C20,'Price List'!$C$3:$C$20,0)),IFERROR(INDEX($H$5:$H$5,MATCH($C20,$A$5:$A$5,0)),0)) -> 0
A21: ANU-S | B21: AC220V | C21: TM3AQ2 | D21: 1 | E21: =IFERROR(INDEX('Price List'!$I$3:$I$20,MATCH($C21,'Price List'!$C$3:$C$20,0)),IFERROR(INDEX($D$5:$D$5,MATCH($C21,$A$5:$A$5,0)),0)) -> 138400 | F21: =D21*E21 -> 138400 | G21: =D21*IFERROR(INDEX('Price List'!$K$3:$K$20,MATCH($C21,'Price List'!$C$3:$C$20,0)),IFERROR(INDEX($E$5:$E$5,MATCH($C21,$A$5:$A$5,0)),0)) -> 0 | H21: =D21*(IFERROR(INDEX('Price List'!$L$3:$L$20,MATCH($C21,'Price List'!$C$3:$C$20,0)),IFERROR(INDEX($F$5:$F$5,MATCH($C21,$A$5:$A$5,0)),0))+IFERROR(INDEX('Price List'!$M$3:$M$20,MATCH($C21,'Price List'!$C$3:$C$20,0)),0)) -> 0 | I21: =D21*IFERROR(INDEX('Price List'!$M$3:$M$20,MATCH($C21,'Price List'!$C$3:$C$20,0)),0) -> 0 | J21: =D21*IFERROR(INDEX('Price List'!$O$3:$O$20,MATCH($C21,'Price List'!$C$3:$C$20,0)),0) -> 2 | K21: =D21*IFERROR(INDEX('Price List'!$P$3:$P$20,MATCH($C21,'Price List'!$C$3:$C$20,0)),IFERROR(INDEX($G$5:$G$5,MATCH($C21,$A$5:$A$5,0)),0)) -> 0 | L21: =D21*IFERROR(INDEX('Price List'!$Q$3:$Q$20,MATCH($C21,'Price List'!$C$3:$C$20,0)),IFERROR(INDEX($H$5:$H$5,MATCH($C21,$A$5:$A$5,0)),0)) -> 0
A22: ANU-S | B22: AC220V | C22: 소계 | F22: =SUM(F20:F21) -> 523150 | G22: =SUM(G20:G21) -> 14 | H22: =SUM(H20:H21) -> 10 | I22: =SUM(I20:I21) -> 6 | J22: =SUM(J20:J21) -> 2 | K22: =SUM(K20:K21) -> 2 | L22: =SUM(L20:L21) -> 0 | M22: =INDEX(요약!$C$4:$C$7,MATCH($A22,요약!$A$4:$A$7,0)) -> 50 | N22: =F22*M22 -> 26157500 | O22: =IF(AND(G22>='기준사양 매칭'!H29,H22>='기준사양 매칭'!K29,J22>='기준사양 매칭'!L29,K22>='기준사양 매칭'!M29,L22>='기준사양 매칭'!N29),"충족",IF(G22<'기준사양 매칭'!H29,"DI "&('기준사양 매칭'!H29-G22)&" 부족 ","")&IF(H22<'기준사양 매칭'!K29,"DO "&('기준사양 매칭'!K29-H22)&" 부족 ","")&IF(J22<'기준사양 매칭'!L29,"AO "&('기준사양 매칭'!L29-J22)&" 부족 ","")&IF(K22<'기준사양 매칭'!M29,"Serial "&('기준사양 매칭'!M29-K22)&" 부족 ","")&IF(L22<'기준사양 매칭'!N29,"ETH "&('기준사양 매칭'!N29-L22)&" 부족 ","")) -> 충족
A24: ANU-S | B24: DC24V | C24: TM241C24T | D24: 1 | E24: =IFERROR(INDEX('Price List'!$I$3:$I$20,MATCH($C24,'Price List'!$C$3:$C$20,0)),IFERROR(INDEX($D$5:$D$5,MATCH($C24,$A$5:$A$5,0)),0)) -> 392850 | F24: =D24*E24 -> 392850 | G24: =D24*IFERROR(INDEX('Price List'!$K$3:$K$20,MATCH($C24,'Price List'!$C$3:$C$20,0)),IFERROR(INDEX($E$5:$E$5,MATCH($C24,$A$5:$A$5,0)),0)) -> 14 | H24: =D24*(IFERROR(INDEX('Price List'!$L$3:$L$20,MATCH($C24,'Price List'!$C$3:$C$20,0)),IFERROR(INDEX($F$5:$F$5,MATCH($C24,$A$5:$A$5,0)),0))+IFERROR(INDEX('Price List'!$M$3:$M$20,MATCH($C24,'Price List'!$C$3:$C$20,0)),0)) -> 10 | I24: =D24*IFERROR(INDEX('Price List'!$M$3:$M$20,MATCH($C24,'Price List'!$C$3:$C$20,0)),0) -> 0 | J24: =D24*IFERROR(INDEX('Price List'!$O$3:$O$20,MATCH($C24,'Price List'!$C$3:$C$20,0)),0) -> 0 | K24: =D24*IFERROR(INDEX('Price List'!$P$3:$P$20,MATCH($C24,'Price List'!$C$3:$C$20,0)),IFERROR(INDEX($G$5:$G$5,MATCH($C24,$A$5:$A$5,0)),0)) -> 2 | L24: =D24*IFERROR(INDEX('Price List'!$Q$3:$Q$20,MATCH($C24,'Price List'!$C$3:$C$20,0)),IFERROR(INDEX($H$5:$H$5,MATCH($C24,$A$5:$A$5,0)),0)) -> 0
A25: ANU-S | B25: DC24V | C25: TM3AQ2 | D25: 1 | E25: =IFERROR(INDEX('Price List'!$I$3:$I$20,MATCH($C25,'Price List'!$C$3:$C$20,0)),IFERROR(INDEX($D$5:$D$5,MATCH($C25,$A$5:$A$5,0)),0)) -> 138400 | F25: =D25*E25 -> 138400 | G25: =D25*IFERROR(INDEX('Price List'!$K$3:$K$20,MATCH($C25,'Price List'!$C$3:$C$20,0)),IFERROR(INDEX($E$5:$E$5,MATCH($C25,$A$5:$A$5,0)),0)) -> 0 | H25: =D25*(IFERROR(INDEX('Price List'!$L$3:$L$20,MATCH($C25,'Price List'!$C$3:$C$20,0)),IFERROR(INDEX($F$5:$F$5,MATCH($C25,$A$5:$A$5,0)),0))+IFERROR(INDEX('Price List'!$M$3:$M$20,MATCH($C25,'Price List'!$C$3:$C$20,0)),0)) -> 0 | I25: =D25*IFERROR(INDEX('Price List'!$M$3:$M$20,MATCH($C25,'Price List'!$C$3:$C$20,0)),0) -> 0 | J25: =D25*IFERROR(INDEX('Price List'!$O$3:$O$20,MATCH($C25,'Price List'!$C$3:$C$20,0)),0) -> 2 | K25: =D25*IFERROR(INDEX('Price List'!$P$3:$P$20,MATCH($C25,'Price List'!$C$3:$C$20,0)),IFERROR(INDEX($G$5:$G$5,MATCH($C25,$A$5:$A$5,0)),0)) -> 0 | L25: =D25*IFERROR(INDEX('Price List'!$Q$3:$Q$20,MATCH($C25,'Price List'!$C$3:$C$20,0)),IFERROR(INDEX($H$5:$H$5,MATCH($C25,$A$5:$A$5,0)),0)) -> 0
A26: ANU-S | B26: DC24V | C26: 소계 | F26: =SUM(F24:F25) -> 531250 | G26: =SUM(G24:G25) -> 14 | H26: =SUM(H24:H25) -> 10 | I26: =SUM(I24:I25) -> 0 | J26: =SUM(J24:J25) -> 2 | K26: =SUM(K24:K25) -> 2 | L26: =SUM(L24:L25) -> 0 | M26: =INDEX(요약!$C$4:$C$7,MATCH($A26,요약!$A$4:$A$7,0)) -> 50 | N26: =F26*M26 -> 26562500 | O26: =IF(AND(G26>='기준사양 매칭'!H29,H26>='기준사양 매칭'!K29,J26>='기준사양 매칭'!L29,K26>='기준사양 매칭'!M29,L26>='기준사양 매칭'!N29),"충족",IF(G26<'기준사양 매칭'!H29,"DI "&('기준사양 매칭'!H29-G26)&" 부족 ","")&IF(H26<'기준사양 매칭'!K29,"DO "&('기준사양 매칭'!K29-H26)&" 부족 ","")&IF(J26<'기준사양 매칭'!L29,"AO "&('기준사양 매칭'!L29-J26)&" 부족 ","")&IF(K26<'기준사양 매칭'!M29,"Serial "&('기준사양 매칭'!M29-K26)&" 부족 ","")&IF(L26<'기준사양 매칭'!N29,"ETH "&('기준사양 매칭'!N29-L26)&" 부족 ","")) -> 충족
A28: MCC | B28: DC24V | C28: TM241CE40T | D28: 1 | E28: =IFERROR(INDEX('Price List'!$I$3:$I$20,MATCH($C28,'Price List'!$C$3:$C$20,0)),IFERROR(INDEX($D$5:$D$5,MATCH($C28,$A$5:$A$5,0)),0)) -> 423450 | F28: =D28*E28 -> 423450 | G28: =D28*IFERROR(INDEX('Price List'!$K$3:$K$20,MATCH($C28,'Price List'!$C$3:$C$20,0)),IFERROR(INDEX($E$5:$E$5,MATCH($C28,$A$5:$A$5,0)),0)) -> 24 | H28: =D28*(IFERROR(INDEX('Price List'!$L$3:$L$20,MATCH($C28,'Price List'!$C$3:$C$20,0)),IFERROR(INDEX($F$5:$F$5,MATCH($C28,$A$5:$A$5,0)),0))+IFERROR(INDEX('Price List'!$M$3:$M$20,MATCH($C28,'Price List'!$C$3:$C$20,0)),0)) -> 16 | I28: =D28*IFERROR(INDEX('Price List'!$M$3:$M$20,MATCH($C28,'Price List'!$C$3:$C$20,0)),0) -> 0 | J28: =D28*IFERROR(INDEX('Price List'!$O$3:$O$20,MATCH($C28,'Price List'!$C$3:$C$20,0)),0) -> 0 | K28: =D28*IFERROR(INDEX('Price List'!$P$3:$P$20,MATCH($C28,'Price List'!$C$3:$C$20,0)),IFERROR(INDEX($G$5:$G$5,MATCH($C28,$A$5:$A$5,0)),0)) -> 2 | L28: =D28*IFERROR(INDEX('Price List'!$Q$3:$Q$20,MATCH($C28,'Price List'!$C$3:$C$20,0)),IFERROR(INDEX($H$5:$H$5,MATCH($C28,$A$5:$A$5,0)),0)) -> 1
A29: MCC | B29: DC24V | C29: TM3DI16 | D29: 2 | E29: =IFERROR(INDEX('Price List'!$I$3:$I$20,MATCH($C29,'Price List'!$C$3:$C$20,0)),IFERROR(INDEX($D$5:$D$5,MATCH($C29,$A$5:$A$5,0)),0)) -> 91200 | F29: =D29*E29 -> 182400 | G29: =D29*IFERROR(INDEX('Price List'!$K$3:$K$20,MATCH($C29,'Price List'!$C$3:$C$20,0)),IFERROR(INDEX($E$5:$E$5,MATCH($C29,$A$5:$A$5,0)),0)) -> 32 | H29: =D29*(IFERROR(INDEX('Price List'!$L$3:$L$20,MATCH($C29,'Price List'!$C$3:$C$20,0)),IFERROR(INDEX($F$5:$F$5,MATCH($C29,$A$5:$A$5,0)),0))+IFERROR(INDEX('Price List'!$M$3:$M$20,MATCH($C29,'Price List'!$C$3:$C$20,0)),0)) -> 0 | I29: =D29*IFERROR(INDEX('Price List'!$M$3:$M$20,MATCH($C29,'Price List'!$C$3:$C$20,0)),0) -> 0 | J29: =D29*IFERROR(INDEX('Price List'!$O$3:$O$20,MATCH($C29,'Price List'!$C$3:$C$20,0)),0) -> 0 | K29: =D29*IFERROR(INDEX('Price List'!$P$3:$P$20,MATCH($C29,'Price List'!$C$3:$C$20,0)),IFERROR(INDEX($G$5:$G$5,MATCH($C29,$A$5:$A$5,0)),0)) -> 0 | L29: =D29*IFERROR(INDEX('Price List'!$Q$3:$Q$20,MATCH($C29,'Price List'!$C$3:$C$20,0)),IFERROR(INDEX($H$5:$H$5,MATCH($C29,$A$5:$A$5,0)),0)) -> 0
A30: MCC | B30: DC24V | C30: TM3DI8 | D30: 1 | E30: =IFERROR(INDEX('Price List'!$I$3:$I$20,MATCH($C30,'Price List'!$C$3:$C$20,0)),IFERROR(INDEX($D$5:$D$5,MATCH($C30,$A$5:$A$5,0)),0)) -> 80800 | F30: =D30*E30 -> 80800 | G30: =D30*IFERROR(INDEX('Price List'!$K$3:$K$20,MATCH($C30,'Price List'!$C$3:$C$20,0)),IFERROR(INDEX($E$5:$E$5,MATCH($C30,$A$5:$A$5,0)),0)) -> 8 | H30: =D30*(IFERROR(INDEX('Price List'!$L$3:$L$20,MATCH($C30,'Price List'!$C$3:$C$20,0)),IFERROR(INDEX($F$5:$F$5,MATCH($C30,$A$5:$A$5,0)),0))+IFERROR(INDEX('Price List'!$M$3:$M$20,MATCH($C30,'Price List'!$C$3:$C$20,0)),0)) -> 0 | I30: =D30*IFERROR(INDEX('Price List'!$M$3:$M$20,MATCH($C30,'Price List'!$C$3:$C$20,0)),0) -> 0 | J30: =D30*IFERROR(INDEX('Price List'!$O$3:$O$20,MATCH($C30,'Price List'!$C$3:$C$20,0)),0) -> 0 | K30: =D30*IFERROR(INDEX('Price List'!$P$3:$P$20,MATCH($C30,'Price List'!$C$3:$C$20,0)),IFERROR(INDEX($G$5:$G$5,MATCH($C30,$A$5:$A$5,0)),0)) -> 0 | L30: =D30*IFERROR(INDEX('Price List'!$Q$3:$Q$20,MATCH($C30,'Price List'!$C$3:$C$20,0)),IFERROR(INDEX($H$5:$H$5,MATCH($C30,$A$5:$A$5,0)),0)) -> 0
A31: MCC | B31: DC24V | C31: TM3DQ16T | D31: 1 | E31: =IFERROR(INDEX('Price List'!$I$3:$I$20,MATCH($C31,'Price List'!$C$3:$C$20,0)),IFERROR(INDEX($D$5:$D$5,MATCH($C31,$A$5:$A$5,0)),0)) -> 90800 | F31: =D31*E31 -> 90800 | G31: =D31*IFERROR(INDEX('Price List'!$K$3:$K$20,MATCH($C31,'Price List'!$C$3:$C$20,0)),IFERROR(INDEX($E$5:$E$5,MATCH($C31,$A$5:$A$5,0)),0)) -> 0 | H31: =D31*(IFERROR(INDEX('Price List'!$L$3:$L$20,MATCH($C31,'Price List'!$C$3:$C$20,0)),IFERROR(INDEX($F$5:$F$5,MATCH($C31,$A$5:$A$5,0)),0))+IFERROR(INDEX('Price List'!$M$3:$M$20,MATCH($C31,'Price List'!$C$3:$C$20,0)),0)) -> 16 | I31: =D31*IFERROR(INDEX('Price List'!$M$3:$M$20,MATCH($C31,'Price List'!$C$3:$C$20,0)),0) -> 0 | J31: =D31*IFERROR(INDEX('Price List'!$O$3:$O$20,MATCH($C31,'Price List'!$C$3:$C$20,0)),0) -> 0 | K31: =D31*IFERROR(INDEX('Price List'!$P$3:$P$20,MATCH($C31,'Price List'!$C$3:$C$20,0)),IFERROR(INDEX($G$5:$G$5,MATCH($C31,$A$5:$A$5,0)),0)) -> 0 | L31: =D31*IFERROR(INDEX('Price List'!$Q$3:$Q$20,MATCH($C31,'Price List'!$C$3:$C$20,0)),IFERROR(INDEX($H$5:$H$5,MATCH($C31,$A$5:$A$5,0)),0)) -> 0
A32: MCC | B32: DC24V | C32: TM3DQ8T | D32: 1 | E32: =IFERROR(INDEX('Price List'!$I$3:$I$20,MATCH($C32,'Price List'!$C$3:$C$20,0)),IFERROR(INDEX($D$5:$D$5,MATCH($C32,$A$5:$A$5,0)),0)) -> 67200 | F32: =D32*E32 -> 67200 | G32: =D32*IFERROR(INDEX('Price List'!$K$3:$K$20,MATCH($C32,'Price List'!$C$3:$C$20,0)),IFERROR(INDEX($E$5:$E$5,MATCH($C32,$A$5:$A$5,0)),0)) -> 0 | H32: =D32*(IFERROR(INDEX('Price List'!$L$3:$L$20,MATCH($C32,'Price List'!$C$3:$C$20,0)),IFERROR(INDEX($F$5:$F$5,MATCH($C32,$A$5:$A$5,0)),0))+IFERROR(INDEX('Price List'!$M$3:$M$20,MATCH($C32,'Price List'!$C$3:$C$20,0)),0)) -> 8 | I32: =D32*IFERROR(INDEX('Price List'!$M$3:$M$20,MATCH($C32,'Price List'!$C$3:$C$20,0)),0) -> 0 | J32: =D32*IFERROR(INDEX('Price List'!$O$3:$O$20,MATCH($C32,'Price List'!$C$3:$C$20,0)),0) -> 0 | K32: =D32*IFERROR(INDEX('Price List'!$P$3:$P$20,MATCH($C32,'Price List'!$C$3:$C$20,0)),IFERROR(INDEX($G$5:$G$5,MATCH($C32,$A$5:$A$5,0)),0)) -> 0 | L32: =D32*IFERROR(INDEX('Price List'!$Q$3:$Q$20,MATCH($C32,'Price List'!$C$3:$C$20,0)),IFERROR(INDEX($H$5:$H$5,MATCH($C32,$A$5:$A$5,0)),0)) -> 0
A33: MCC | B33: DC24V | C33: TM3AQ2 | D33: 1 | E33: =IFERROR(INDEX('Price List'!$I$3:$I$20,MATCH($C33,'Price List'!$C$3:$C$20,0)),IFERROR(INDEX($D$5:$D$5,MATCH($C33,$A$5:$A$5,0)),0)) -> 138400 | F33: =D33*E33 -> 138400 | G33: =D33*IFERROR(INDEX('Price List'!$K$3:$K$20,MATCH($C33,'Price List'!$C$3:$C$20,0)),IFERROR(INDEX($E$5:$E$5,MATCH($C33,$A$5:$A$5,0)),0)) -> 0 | H33: =D33*(IFERROR(INDEX('Price List'!$L$3:$L$20,MATCH($C33,'Price List'!$C$3:$C$20,0)),IFERROR(INDEX($F$5:$F$5,MATCH($C33,$A$5:$A$5,0)),0))+IFERROR(INDEX('Price List'!$M$3:$M$20,MATCH($C33,'Price List'!$C$3:$C$20,0)),0)) -> 0 | I33: =D33*IFERROR(INDEX('Price List'!$M$3:$M$20,MATCH($C33,'Price List'!$C$3:$C$20,0)),0) -> 0 | J33: =D33*IFERROR(INDEX('Price List'!$O$3:$O$20,MATCH($C33,'Price List'!$C$3:$C$20,0)),0) -> 2 | K33: =D33*IFERROR(INDEX('Price List'!$P$3:$P$20,MATCH($C33,'Price List'!$C$3:$C$20,0)),IFERROR(INDEX($G$5:$G$5,MATCH($C33,$A$5:$A$5,0)),0)) -> 0 | L33: =D33*IFERROR(INDEX('Price List'!$Q$3:$Q$20,MATCH($C33,'Price List'!$C$3:$C$20,0)),IFERROR(INDEX($H$5:$H$5,MATCH($C33,$A$5:$A$5,0)),0)) -> 0
A34: MCC | B34: DC24V | C34: 소계 | F34: =SUM(F28:F33) -> 983050 | G34: =SUM(G28:G33) -> 64 | H34: =SUM(H28:H33) -> 40 | I34: =SUM(I28:I33) -> 0 | J34: =SUM(J28:J33) -> 2 | K34: =SUM(K28:K33) -> 2 | L34: =SUM(L28:L33) -> 1 | M34: =INDEX(요약!$C$4:$C$7,MATCH($A34,요약!$A$4:$A$7,0)) -> 100 | N34: =F34*M34 -> 98305000 | O34: =IF(AND(G34>='기준사양 매칭'!H42,H34>='기준사양 매칭'!K42,I34>='기준사양 매칭'!K42,J34>='기준사양 매칭'!L42,K34>='기준사양 매칭'!M42,L34>='기준사양 매칭'!N42),"충족",IF(G34<'기준사양 매칭'!H42,"DI "&('기준사양 매칭'!H42-G34)&" 부족 ","")&IF(H34<'기준사양 매칭'!K42,"DO "&('기준사양 매칭'!K42-H34)&" 부족 ","")&IF(I34<'기준사양 매칭'!K42,"Relay DO "&('기준사양 매칭'!K42-I34)&" 부족 ","")&IF(J34<'기준사양 매칭'!L42,"AO "&('기준사양 매칭'!L42-J34)&" 부족 ","")&IF(K34<'기준사양 매칭'!M42,"Serial "&('기준사양 매칭'!M42-K34)&" 부족 ","")&IF(L34<'기준사양 매칭'!N42,"ETH "&('기준사양 매칭'!N42-L34)&" 부족 ","")) -> DI 38 부족 DO 14 부족 Relay DO 54 부족 AO 2 부족
A36: 연간 금액 비교
A37: 시스템 | B37: 연간 수량 | C37: Schneider DC24V | D37: Schneider AC220V (MCC는 DC) | E37: Claude 안B (DC24V, RFQ 준수) | F37: Claude 안A (DC24V + Relay) | G37: Schneider DC − 안B
A38: TSU | B38: =요약!C4 -> 200 | C38: =N12 -> 78570000 | D38: =N9 -> 76950000 | E38: =요약!H4 -> 78570000 | F38: =요약!G4 -> 91450000 | G38: =C38-E38 -> 0
A39: ANU | B39: =요약!C5 -> 300 | C39: =N18 -> 125280000 | D39: =N15 -> 121905000 | E39: =요약!H5 -> 166800000 | F39: =요약!G5 -> 186615000 | G39: =C39-E39 -> -41520000
A40: ANU-S | B40: =요약!C6 -> 50 | C40: =N26 -> 26562500 | D40: =N22 -> 26157500 | E40: =요약!H6 -> 26562500 | F40: =요약!G6 -> 29782500 | G40: =C40-E40 -> 0
A41: MCC | B41: =요약!C7 -> 100 | C41: =N34 -> 98305000 | D41: =N34 -> 98305000 | E41: =요약!H7 -> 144950000 | F41: =요약!G7 -> 144950000 | G41: =C41-E41 -> -46645000
A42: 합계 | B42: =SUM(B38:B41) -> 650 | C42: =SUM(C38:C41) -> 328717500 | D42: =SUM(D38:D41) -> 323317500 | E42: =SUM(E38:E41) -> 416882500 | F42: =SUM(F38:F41) -> 452797500 | G42: =SUM(G38:G41) -> -88165000
A43: ※ Schneider MCC 금액은 RFQ 미준수(Tr 출력, 점수 부족) 구성 + CE40T 추정 단가 기준이라 안B와 직접 비교 불가.
A45: 검토 결과 — Schneider 제안 vs RFQ (PLC 사양서 R3.1)
A46: 1. [RFQ 위반] MCC는 'Relay Type Only'(공통사항 5)인데 제안 DO 40점이 전부 Tr(TM241CE40T 내장 Tr 16 + TM3DQ16T + TM3DQ8T). DC24V Relay 구성은 TM241CE24T/CE40T + TM3DQ16R이어야 함(Claude 안A/B의 MCC 구성).
A47: 2. [점수 부족] MCC 제안 DI 64 / DO 40 / AO 2 — 현행 유지 요구 DI 102 / DO 54 / AO 4 대비 DI 38, DO 14, AO 2 부족. Card 구성 ±10% 허용을 감안해도 미달. 현행 점수 유지 시 TM3 모듈이 7개를 넘어 버스 확장(TM3XTRA1/TM3XREC1) 필요 — 견적에 포함 요청.
A48: 3. [가격] MCC CPU TM241CE40T는 가격표에 없음(노란 칸 = 추정). Table1 '제안 가격' 행도 비어 있음 → 품목별 단가와 함께 2027년 가격 기준 견적 회신 요청(공통사항 7). 현재 Price List가 2027년 기준인지도 확인 필요.
A49: 4. [오기] 제안서 ANU-S 필수사항이 DI 6 / DO 12 / AO 1로 적혀 있음(ANU 값 복사로 보임). RFQ 값은 DI 3 / DO 5 / AO 1 — RFQ 기준으로는 TM241C24x + TM3AQ2로 충족.
A50: 5. [오기] MCC 슬라이드 'TM3DI18' → TM3DI8(Table1과 일치). MCC 슬라이드 사진은 Relay CPU(TM241C40R) 이미지로 표 내용(CE40T)과 다름.
...
