Workbook

Sheet 요약
A1: PLC 교체 견적 — 최종 (ABB → Schneider M241)
A2: 기준: Techross RFQ 'PLC 사양서 R3.1' + 기존 사양 (MCC는 현행 유지 점수, 출력 Relay·TR 무관) · 매입가 = Schneider 협의 할인율 (CPU 0.40 / 모듈 0.35) · 단위: 원 · 2026-10-06
A3: 노란 칸 | B3: ← 바꿔도 되는 값 (바꾸면 금액이 자동으로 다시 계산됩니다)
A5: 프로젝트 | B5: 기존 PLC (ABB) | C5: 연간 구매수량 (대) | D5: 1대 가격 DC24V (권장) | E5: 1대 가격 AC220V | F5: 연간 금액 DC24V (권장) | G5: 연간 금액 AC220V
A6: TSU | B6: ABB PM554-RP + DO571 | C6: 200 | D6: ='프로젝트별 구성'!F9 -> 349200 | E6: ='프로젝트별 구성'!F11 -> 342000 | F6: =C6*D6 -> 69840000 | G6: =C6*E6 -> 68400000
A7: ANU | B7: ABB PM554-RP + DO571 + AO561 | C7: 300 | D7: ='프로젝트별 구성'!F19 -> 371200 | E7: ='프로젝트별 구성'!F21 -> 361200 | F7: =C7*D7 -> 111360000 | G7: =C7*E7 -> 108360000
A8: ANU-S | B8: ABB PM564-RP | C8: 50 | D8: ='프로젝트별 구성'!F30 -> 470300 | E8: ='프로젝트별 구성'!F33 -> 463100 | F8: =C8*D8 -> 23515000 | G8: =C8*E8 -> 23155000
A9: MCC | B9: ABB PM564-RP-ETH + DI562×6 + DO573×3 + AO561×2 | C9: 100 | D9: ='프로젝트별 구성'!F47 -> 1226900 | E9: DC24V만 가능 | F9: =C9*D9 -> 122690000 | G9: =F9 -> 122690000
A10: 합계 | C10: =SUM(C6:C9) -> 650 | F10: =SUM(F6:F9) -> 327405000 | G10: =SUM(G6:G9) -> 322605000
A11: ※ AC220V 연간 금액 합계에는 MCC를 DC24V 가격으로 넣었습니다 (MCC는 DC24V만 가능).
A13: 프로젝트별 최종 구성
A14: 프로젝트 | B14: DC24V (권장) | D14: AC220V | F14: 제공 점수
A15: TSU | B15: TM241C24T | D15: TM241C24R | F15: 입력 14 / 출력 10 / Serial 2CH
A16: ANU | B16: TM241C40T | D16: TM241C40R | F16: 입력 24 / 출력 16 / Serial 2CH
A17: ANU-S | B17: TM241C24T + TM3AQ2 | D17: TM241C24R + TM3AQ2 | F17: 입력 14 / 출력 10 / AO 2 / Serial 2CH
A18: MCC | B18: TM241CE40T + TM3DI16×5 + TM3DQ16T×2 + TM3DQ8T + TM3AQ4 + TM3XTRA1·XREC1 | D18: DC24V만 | F18: 입력 104 / 출력 56 / AO 4 Serial 2CH + 이더넷
A20: 핵심 정리
A21: ="① 연간 구매금액: DC24V 기준 약 "&TEXT(F10/100000000,"0.00")&"억 원, AC220V 기준 약 "&TEXT(G10/100000000,"0.00")&"억 원" -> ① 연간 구매금액: DC24V 기준 약 3.27억 원, AC220V 기준 약 3.23억 원
A22: ② TSU · ANU · ANU-S: Schneider 제안 구성 그대로 — Techross 요구 충족.
A23: ③ MCC: 기존 사양(현행 유지: 입력 102 / 출력 54 / AO 4) 기준으로 구성. 출력은 Relay·TR 무관(Techross 확인)이라 TR 모듈 사용. 확장 모듈 9개 → 버스 확장 포함.
A24: ="④ MCC 가격 (Schneider 협의 할인율 반영): 1대 "&TEXT(D9,"#,##0")&"원, 연간 "&TEXT(F9,"#,##0")&"원 — 버스 확장(TM3XTRA1/XREC1) 포함" -> ④ MCC 가격 (Schneider 협의 할인율 반영): 1대 1,226,900원, 연간 122,690,000원 — 버스 확장(TM3XTRA1/XREC1) 포함
A25: ⑤ ANU: 기존 AO561(아날로그 출력)은 RFQ 필수 사양에 없어 뺐습니다. 실제로 쓰고 있다면 1대당 138,400원 추가.
A26: ="⑥ CPU 할인율을 협의값 "&TEXT('CPU 할인 효과'!B3,"0.00")&"에서 "&TEXT('CPU 할인 효과'!B4,"0.00")&"까지 더 받으면 연간 약 "&TEXT('CPU 할인 효과'!H13/10000,"#,##0")&"만 원 추가 절감 (DC24V 기준)" -> ⑥ CPU 할인율을 협의값 0.40에서 0.35까지 더 받으면 연간 약 2,943만 원 추가 절감 (DC24V 기준)
A27: ⑦ 받은 단가가 2027년 가격 기준인지 확인이 필요합니다 (RFQ 조건).
A28: ="⑧ LS 타겟 기준 연간 마진 (DC24V): "&IF(ISNUMBER('마진 계산'!E30),TEXT('마진 계산'!E30,"#,##0")&"원 (마진율 "&TEXT('마진 계산'!F30,"0.0%")&") / 희망 마진("&TEXT('마진 계산'!B4,"0%")&")까지 연간 추가 특가 "&TEXT('마진 계산'!G30,"#,##0")&"원 (프로젝트별로 각각 맞출 때) — 묶음 전체로는 "&IF('마진 계산'!F30>='마진 계산'!B4,"추가 특가 없이 달성","추가 특가 필요"),"LS 타겟 프라이스를 '마진 계산' 시트에 넣으면 여기에 표시됩니다") -> ⑧ LS 타겟 기준 연간 마진 (DC24V): 114,495,000원 (마진율 25.9%) / 희망 마진(20%)까지 연간 추가 특가 29,090,000원 (프로젝트별로 각각 맞출 때) — 묶음 전체로는 추가 특가 없이 달성
A29: =IF(NOT(ISNUMBER('마진 계산'!F14)),"⑨ MCC 마진: LS 타겟을 넣으면 표시됩니다",IF('마진 계산'!F14<0,"⑨ MCC는 LS 타겟 대비 1대 "&TEXT('마진 계산'!F14,"#,##0")&"원 ("&TEXT('마진 계산'!G14,"0.0%")&"), 연 "&TEXT('마진 계산'!I14,"#,##0")&"원 손실 → 묶음 전체 마진("&TEXT('마진 계산'!F30,"0.0%")&")으로 흡수","⑨ MCC 마진: 1대 "&TEXT('마진 계산'!F14,"#,##0")&"원 ("&TEXT('마진 계산'!G14,"0.0%")&")")) -> ⑨ MCC는 LS 타겟 대비 1대 -56,900원 (-4.9%), 연 -5,690,000원 손실 → 묶음 전체 마진(25.9%)으로 흡수

Sheet 마진 계산
A1: LS 타겟 프라이스 → 우리 마진 & 필요한 추가 특가
A2: 사용법: ① 노란 칸에 LS 타겟 프라이스(1대) 입력 ② 희망 마진율 입력 → 지금 마진, 그리고 희망 마진을 남기려면 Schneider에 얼마나 더 깎아야 하는지 바로 나옵니다.
A4: 희망 마진율 | B4: 0.2 | C4: ← 우리가 남기고 싶은 마진율 (판매가 기준)
A6: ① 지금 단가(현재 DF)로 LS 타겟 가격에 팔면
A7: 프로젝트 | B7: 전원 | C7: 연간 수량 (대) | D7: LS 타겟 프라이스 (1대) | E7: 현재 매입가 (1대) | F7: 마진 (1대) | G7: 마진율 | H7: 연간 매출 | I7: 연간 마진
A8: TSU | B8: DC24V | C8: =요약!C6 -> 200 | D8: 494000 | E8: ='프로젝트별 구성'!F9 -> 349200 | F8: =IF(D8="","",D8-E8) -> 144800 | G8: =IF(OR(D8="",D8=0),"",F8/D8) -> 0.29311741 | H8: =IF(D8="","",C8*D8) -> 98800000 | I8: =IF(D8="","",C8*F8) -> 28960000 | J8: ← 마이너스면 빨간색
A9: TSU | B9: AC220V | C9: =요약!C6 -> 200 | D9: 494000 | E9: ='프로젝트별 구성'!F11 -> 342000 | F9: =IF(D9="","",D9-E9) -> 152000 | G9: =IF(OR(D9="",D9=0),"",F9/D9) -> 0.30769231 | H9: =IF(D9="","",C9*D9) -> 98800000 | I9: =IF(D9="","",C9*F9) -> 30400000
A10: ANU | B10: DC24V | C10: =요약!C7 -> 300 | D10: 646000 | E10: ='프로젝트별 구성'!F19 -> 371200 | F10: =IF(D10="","",D10-E10) -> 274800 | G10: =IF(OR(D10="",D10=0),"",F10/D10) -> 0.425387 | H10: =IF(D10="","",C10*D10) -> 193800000 | I10: =IF(D10="","",C10*F10) -> 82440000
A11: ANU | B11: AC220V | C11: =요약!C7 -> 300 | D11: 646000 | E11: ='프로젝트별 구성'!F21 -> 361200 | F11: =IF(D11="","",D11-E11) -> 284800 | G11: =IF(OR(D11="",D11=0),"",F11/D11) -> 0.44086687 | H11: =IF(D11="","",C11*D11) -> 193800000 | I11: =IF(D11="","",C11*F11) -> 85440000
A12: ANU-S | B12: DC24V | C12: =요약!C8 -> 50 | D12: 646000 | E12: ='프로젝트별 구성'!F30 -> 470300 | F12: =IF(D12="","",D12-E12) -> 175700 | G12: =IF(OR(D12="",D12=0),"",F12/D12) -> 0.27198142 | H12: =IF(D12="","",C12*D12) -> 32300000 | I12: =IF(D12="","",C12*F12) -> 8785000
A13: ANU-S | B13: AC220V | C13: =요약!C8 -> 50 | D13: 646000 | E13: ='프로젝트별 구성'!F33 -> 463100 | F13: =IF(D13="","",D13-E13) -> 182900 | G13: =IF(OR(D13="",D13=0),"",F13/D13) -> 0.28312693 | H13: =IF(D13="","",C13*D13) -> 32300000 | I13: =IF(D13="","",C13*F13) -> 9145000
A14: MCC | B14: DC24V | C14: =요약!C9 -> 100 | D14: 1170000 | E14: ='프로젝트별 구성'!F47 -> 1226900 | F14: =IF(D14="","",D14-E14) -> -56900 | G14: =IF(OR(D14="",D14=0),"",F14/D14) -> -0.048632479 | H14: =IF(D14="","",C14*D14) -> 117000000 | I14: =IF(D14="","",C14*F14) -> -5690000
A17: ② 희망 마진율을 남기려면 Schneider에 얼마나 더 받아야 하나
A18: 프로젝트 | B18: 전원 | C18: 허용 매입가 (1대) | D18: 현재 매입가 (1대) | E18: 더 깎아야 할 금액 (1대) | F18: 추가 할인율 (현재 매입가 대비) | G18: 현재 DF (실효) | H18: 필요 DF (실효) | I18: 연간 추가 특가 필요액 | J18: 판정
A19: TSU | B19: DC24V | C19: =IF(D8="","",ROUND(D8*(1-$B$4),0)) -> 395200 | D19: =E8 -> 349200 | E19: =IF(C19="","",MAX(D19-C19,0)) -> 0 | F19: =IF(C19="","",E19/D19) -> 0 | G19: =IFERROR(D19/'프로젝트별 구성'!G9,"") -> 0.4 | H19: =IF(C19="","",IFERROR(MIN(C19,D19)/'프로젝트별 구성'!G9,"")) -> 0.4 | I19: =IF(C19="","",E19*C8) -> 0 | J19: =IF(C19="","타겟 입력 전",IF(E19=0,"OK — 지금 단가로 희망 마진 확보","추가 특가 필요")) -> OK — 지금 단가로 희망 마진 확보
A20: TSU | B20: AC220V | C20: =IF(D9="","",ROUND(D9*(1-$B$4),0)) -> 395200 | D20: =E9 -> 342000 | E20: =IF(C20="","",MAX(D20-C20,0)) -> 0 | F20: =IF(C20="","",E20/D20) -> 0 | G20: =IFERROR(D20/'프로젝트별 구성'!G11,"") -> 0.4 | H20: =IF(C20="","",IFERROR(MIN(C20,D20)/'프로젝트별 구성'!G11,"")) -> 0.4 | I20: =IF(C20="","",E20*C9) -> 0 | J20: =IF(C20="","타겟 입력 전",IF(E20=0,"OK — 지금 단가로 희망 마진 확보","추가 특가 필요")) -> OK — 지금 단가로 희망 마진 확보
A21: ANU | B21: DC24V | C21: =IF(D10="","",ROUND(D10*(1-$B$4),0)) -> 516800 | D21: =E10 -> 371200 | E21: =IF(C21="","",MAX(D21-C21,0)) -> 0 | F21: =IF(C21="","",E21/D21) -> 0 | G21: =IFERROR(D21/'프로젝트별 구성'!G19,"") -> 0.4 | H21: =IF(C21="","",IFERROR(MIN(C21,D21)/'프로젝트별 구성'!G19,"")) -> 0.4 | I21: =IF(C21="","",E21*C10) -> 0 | J21: =IF(C21="","타겟 입력 전",IF(E21=0,"OK — 지금 단가로 희망 마진 확보","추가 특가 필요")) -> OK — 지금 단가로 희망 마진 확보
A22: ANU | B22: AC220V | C22: =IF(D11="","",ROUND(D11*(1-$B$4),0)) -> 516800 | D22: =E11 -> 361200 | E22: =IF(C22="","",MAX(D22-C22,0)) -> 0 | F22: =IF(C22="","",E22/D22) -> 0 | G22: =IFERROR(D22/'프로젝트별 구성'!G21,"") -> 0.4 | H22: =IF(C22="","",IFERROR(MIN(C22,D22)/'프로젝트별 구성'!G21,"")) -> 0.4 | I22: =IF(C22="","",E22*C11) -> 0 | J22: =IF(C22="","타겟 입력 전",IF(E22=0,"OK — 지금 단가로 희망 마진 확보","추가 특가 필요")) -> OK — 지금 단가로 희망 마진 확보
A23: ANU-S | B23: DC24V | C23: =IF(D12="","",ROUND(D12*(1-$B$4),0)) -> 516800 | D23: =E12 -> 470300 | E23: =IF(C23="","",MAX(D23-C23,0)) -> 0 | F23: =IF(C23="","",E23/D23) -> 0 | G23: =IFERROR(D23/'프로젝트별 구성'!G30,"") -> 0.38580804 | H23: =IF(C23="","",IFERROR(MIN(C23,D23)/'프로젝트별 구성'!G30,"")) -> 0.38580804 | I23: =IF(C23="","",E23*C12) -> 0 | J23: =IF(C23="","타겟 입력 전",IF(E23=0,"OK — 지금 단가로 희망 마진 확보","추가 특가 필요")) -> OK — 지금 단가로 희망 마진 확보
A24: ANU-S | B24: AC220V | C24: =IF(D13="","",ROUND(D13*(1-$B$4),0)) -> 516800 | D24: =E13 -> 463100 | E24: =IF(C24="","",MAX(D24-C24,0)) -> 0 | F24: =IF(C24="","",E24/D24) -> 0 | G24: =IFERROR(D24/'프로젝트별 구성'!G33,"") -> 0.38559534 | H24: =IF(C24="","",IFERROR(MIN(C24,D24)/'프로젝트별 구성'!G33,"")) -> 0.38559534 | I24: =IF(C24="","",E24*C13) -> 0 | J24: =IF(C24="","타겟 입력 전",IF(E24=0,"OK — 지금 단가로 희망 마진 확보","추가 특가 필요")) -> OK — 지금 단가로 희망 마진 확보
A25: MCC | B25: DC24V | C25: =IF(D14="","",ROUND(D14*(1-$B$4),0)) -> 936000 | D25: =E14 -> 1226900 | E25: =IF(C25="","",MAX(D25-C25,0)) -> 290900 | F25: =IF(C25="","",E25/D25) -> 0.23710164 | G25: =IFERROR(D25/'프로젝트별 구성'!G47,"") -> 0.36363367 | H25: =IF(C25="","",IFERROR(MIN(C25,D25)/'프로젝트별 구성'!G47,"")) -> 0.27741553 | I25: =IF(C25="","",E25*C14) -> 29090000 | J25: =IF(C25="","타겟 입력 전",IF(E25=0,"OK — 지금 단가로 희망 마진 확보","추가 특가 필요")) -> 추가 특가 필요
A26: ※ 허용 매입가 = 타겟 × (1 − 희망 마진율). 실효 DF = 1대 매입가 ÷ 1대 리스트가 합계 (CPU 0.45 · 모듈 0.40이 섞인 평균 할인율). '필요 DF'가 Schneider에 요청할 수준입니다.
A28: ③ 연간 합계 (4개 프로젝트 전부)
A29: 납품 방식 | C29: 연간 매입 | D29: 연간 매출 | E29: 연간 마진 | F29: 마진율 | G29: 희망 마진까지 연간 추가 특가
A30: DC24V로 납품 | C30: =C8*E8+C10*E10+C12*E12+C14*E14 -> 327405000 | D30: =IF((D8="")+(D10="")+(D12="")+(D14="")>0,"타겟 "&((D8="")+(D10="")+(D12="")+(D14=""))&"건 미입력",H8+H10+H12+H14) -> 441900000 | E30: =IF(ISNUMBER(D30),D30-C30,"") -> 114495000 | F30: =IF(ISNUMBER(D30),E30/D30,"") -> 0.25909708 | G30: =IF(ISNUMBER(D30),I19+I21+I23+I25,"") -> 29090000
A31: AC220V로 납품 (MCC는 DC24V) | C31: =C9*E9+C11*E11+C13*E13+C14*E14 -> 322605000 | D31: =IF((D9="")+(D11="")+(D13="")+(D14="")>0,"타겟 "&((D9="")+(D11="")+(D13="")+(D14=""))&"건 미입력",H9+H11+H13+H14) -> 441900000 | E31: =IF(ISNUMBER(D31),D31-C31,"") -> 119295000 | F31: =IF(ISNUMBER(D31),E31/D31,"") -> 0.26995927 | G31: =IF(ISNUMBER(D31),I20+I22+I24+I25,"") -> 29090000
A33: ※ 매입가는 현재 할인율(CPU 0.45 · 모듈 0.40) 기준. MCC는 버스 확장(TM3XTRA1/XREC1)까지 포함된 가격입니다.
A34: ※ LS가 프로젝트별로 한 가격만 주면 AC220V·DC24V 칸에 같은 값을 넣어 비교하세요.
A35: ※ '희망 마진까지 연간 추가 특가'는 프로젝트마다 각각 희망 마진을 맞출 때 필요한 금액입니다. 묶음 전체 마진율(F30·F31)이 희망 마진율 이상이면 추가 특가 없이 목표 달성.

Sheet 프로젝트별 구성
A1: 프로젝트별 PLC 구성
A2: 단가는 '단가표'에서 자동으로 가져옵니다. 1대(1세트) 기준.
A4: TSU
A5: 기존 PLC | B5: ABB PM554-RP + DO571
A6: 필요 사양 | B6: 입력 3 / 출력 6 / 통신 Serial 2CH (+10% 여유)
A7: 전원 | B7: 모델 | C7: 설명 | D7: 수량 | E7: 매입 단가 | F7: 매입 금액 | G7: 리스트가 금액
A8: DC24V (권장) | B8: TM241C24T | C8: =VLOOKUP(B8,단가표!$B$5:$G$25,3,FALSE()) -> CPU (입력 14 / 출력 10) | D8: 1 | E8: =VLOOKUP(B8,단가표!$B$5:$G$25,6,FALSE()) -> 349200 | F8: =D8*E8 -> 349200 | G8: =D8*VLOOKUP(B8,단가표!$B$5:$G$25,4,FALSE()) -> 873000
A9: DC24V 1대 가격 | F9: =SUM(F8:F8) -> 349200 | G9: =SUM(G8:G8) -> 873000
A10: AC220V | B10: TM241C24R | C10: =VLOOKUP(B10,단가표!$B$5:$G$25,3,FALSE()) -> CPU (입력 14 / 출력 10 = 릴레이 6 + TR 4) | D10: 1 | E10: =VLOOKUP(B10,단가표!$B$5:$G$25,6,FALSE()) -> 342000 | F10: =D10*E10 -> 342000 | G10: =D10*VLOOKUP(B10,단가표!$B$5:$G$25,4,FALSE()) -> 855000
A11: AC220V 1대 가격 | F11: =SUM(F10:F10) -> 342000 | G11: =SUM(G10:G10) -> 855000
A12: 제공: 입력 14 / 출력 10 / Serial 2CH → 충족
A14: ANU
A15: 기존 PLC | B15: ABB PM554-RP + DO571 + AO561
A16: 필요 사양 | B16: 입력 6 / 출력 12 / 통신 Serial 2CH (+10% 여유)
A17: 전원 | B17: 모델 | C17: 설명 | D17: 수량 | E17: 매입 단가 | F17: 매입 금액 | G17: 리스트가 금액
A18: DC24V (권장) | B18: TM241C40T | C18: =VLOOKUP(B18,단가표!$B$5:$G$25,3,FALSE()) -> CPU (입력 24 / 출력 16) | D18: 1 | E18: =VLOOKUP(B18,단가표!$B$5:$G$25,6,FALSE()) -> 371200 | F18: =D18*E18 -> 371200 | G18: =D18*VLOOKUP(B18,단가표!$B$5:$G$25,4,FALSE()) -> 928000
A19: DC24V 1대 가격 | F19: =SUM(F18:F18) -> 371200 | G19: =SUM(G18:G18) -> 928000
A20: AC220V | B20: TM241C40R | C20: =VLOOKUP(B20,단가표!$B$5:$G$25,3,FALSE()) -> CPU (입력 24 / 출력 16 = 릴레이 12 + TR 4) | D20: 1 | E20: =VLOOKUP(B20,단가표!$B$5:$G$25,6,FALSE()) -> 361200 | F20: =D20*E20 -> 361200 | G20: =D20*VLOOKUP(B20,단가표!$B$5:$G$25,4,FALSE()) -> 903000
A21: AC220V 1대 가격 | F21: =SUM(F20:F20) -> 361200 | G21: =SUM(G20:G20) -> 903000
A22: 제공: 입력 24 / 출력 16 / Serial 2CH → 충족. ※ 기존 AO561(아날로그 출력)을 쓰고 있다면 TM3AQ2 추가 필요 (+138,400원)
A24: ANU-S
A25: 기존 PLC | B25: ABB PM564-RP
A26: 필요 사양 | B26: 입력 3 / 출력 5 / 아날로그 출력 1CH / 통신 Serial 2CH (+10% 여유)
A27: 전원 | B27: 모델 | C27: 설명 | D27: 수량 | E27: 매입 단가 | F27: 매입 금액 | G27: 리스트가 금액
A28: DC24V (권장) | B28: TM241C24T | C28: =VLOOKUP(B28,단가표!$B$5:$G$25,3,FALSE()) -> CPU (입력 14 / 출력 10) | D28: 1 | E28: =VLOOKUP(B28,단가표!$B$5:$G$25,6,FALSE()) -> 349200 | F28: =D28*E28 -> 349200 | G28: =D28*VLOOKUP(B28,단가표!$B$5:$G$25,4,FALSE()) -> 873000
B29: TM3AQ2 | C29: =VLOOKUP(B29,단가표!$B$5:$G$25,3,FALSE()) -> 아날로그 출력 2CH | D29: 1 | E29: =VLOOKUP(B29,단가표!$B$5:$G$25,6,FALSE()) -> 121100 | F29: =D29*E29 -> 121100 | G29: =D29*VLOOKUP(B29,단가표!$B$5:$G$25,4,FALSE()) -> 346000
A30: DC24V 1대 가격 | F30: =SUM(F28:F29) -> 470300 | G30: =SUM(G28:G29) -> 1219000
A31: AC220V | B31: TM241C24R | C31: =VLOOKUP(B31,단가표!$B$5:$G$25,3,FALSE()) -> CPU (입력 14 / 출력 10 = 릴레이 6 + TR 4) | D31: 1 | E31: =VLOOKUP(B31,단가표!$B$5:$G$25,6,FALSE()) -> 342000 | F31: =D31*E31 -> 342000 | G31: =D31*VLOOKUP(B31,단가표!$B$5:$G$25,4,FALSE()) -> 855000
B32: TM3AQ2 | C32: =VLOOKUP(B32,단가표!$B$5:$G$25,3,FALSE()) -> 아날로그 출력 2CH | D32: 1 | E32: =VLOOKUP(B32,단가표!$B$5:$G$25,6,FALSE()) -> 121100 | F32: =D32*E32 -> 121100 | G32: =D32*VLOOKUP(B32,단가표!$B$5:$G$25,4,FALSE()) -> 346000
A33: AC220V 1대 가격 | F33: =SUM(F31:F32) -> 463100 | G33: =SUM(G31:G32) -> 1201000
A34: 제공: 입력 14 / 출력 10 / 아날로그 출력 2CH / Serial 2CH → 충족
A36: MCC
A37: 기존 PLC | B37: ABB PM564-RP-ETH + DI562×6 + DO573×3 + AO561×2
A38: 필요 사양 | B38: Techross 기준 (현행 유지): 입력 102 / 출력 54 (Relay·TR 무관) / 아날로그 출력 4CH / Serial 1CH + 이더넷 1CH
A39: 전원 | B39: 모델 | C39: 설명 | D39: 수량 | E39: 매입 단가 | F39: 매입 금액 | G39: 리스트가 금액
A40: DC24V (A안) | B40: TM241CE40T | C40: =VLOOKUP(B40,단가표!$B$5:$G$25,3,FALSE()) -> CPU + 이더넷 (입력 24 / 출력 16) | D40: 1 | E40: =VLOOKUP(B40,단가표!$B$5:$G$25,6,FALSE()) -> 368000 | F40: =D40*E40 -> 368000 | G40: =D40*VLOOKUP(B40,단가표!$B$5:$G$25,4,FALSE()) -> 920000
B41: TM3DI16 | C41: =VLOOKUP(B41,단가표!$B$5:$G$25,3,FALSE()) -> 디지털 입력 16점 | D41: 5 | E41: =VLOOKUP(B41,단가표!$B$5:$G$25,6,FALSE()) -> 79800 | F41: =D41*E41 -> 399000 | G41: =D41*VLOOKUP(B41,단가표!$B$5:$G$25,4,FALSE()) -> 1140000
B42: TM3DQ16T | C42: =VLOOKUP(B42,단가표!$B$5:$G$25,3,FALSE()) -> 트랜지스터 출력 16점 | D42: 2 | E42: =VLOOKUP(B42,단가표!$B$5:$G$25,6,FALSE()) -> 79450 | F42: =D42*E42 -> 158900 | G42: =D42*VLOOKUP(B42,단가표!$B$5:$G$25,4,FALSE()) -> 454000
B43: TM3DQ8T | C43: =VLOOKUP(B43,단가표!$B$5:$G$25,3,FALSE()) -> 트랜지스터 출력 8점 | D43: 1 | E43: =VLOOKUP(B43,단가표!$B$5:$G$25,6,FALSE()) -> 58800 | F43: =D43*E43 -> 58800 | G43: =D43*VLOOKUP(B43,단가표!$B$5:$G$25,4,FALSE()) -> 168000
B44: TM3AQ4 | C44: =VLOOKUP(B44,단가표!$B$5:$G$25,3,FALSE()) -> 아날로그 출력 4CH | D44: 1 | E44: =VLOOKUP(B44,단가표!$B$5:$G$25,6,FALSE()) -> 122850 | F44: =D44*E44 -> 122850 | G44: =D44*VLOOKUP(B44,단가표!$B$5:$G$25,4,FALSE()) -> 351000
...

Sheet 연간 BOM
A1: 연간 BOM — 확정 구성 기준 (모델별 연간 소요량)
A2: 연간 수량 = 프로젝트별 1대 구성 × 연간 구매수량('요약' 시트) · 단가 = '단가표' 매입 단가 · MCC는 Techross 기준(A안)
A4: 모델 | B4: 설명 | C4: 단가 | D4: DC24V 납품 연간 수량 | E4: DC24V 납품 연간 금액 | F4: AC220V 납품 연간 수량 | G4: AC220V 납품 연간 금액 | H4: 사용 프로젝트 (1대당 수량)
A5: TM241C24T | B5: =VLOOKUP(A5,단가표!$B$5:$G$25,3,FALSE()) -> CPU (입력 14 / 출력 10) | C5: =VLOOKUP(A5,단가표!$B$5:$G$25,6,FALSE()) -> 349200 | D5: =1*요약!$C$6+1*요약!$C$8 -> 250 | E5: =C5*D5 -> 87300000 | F5: 0 | G5: =C5*F5 -> 0 | H5: TSU, ANU-S
A6: TM241C24R | B6: =VLOOKUP(A6,단가표!$B$5:$G$25,3,FALSE()) -> CPU (입력 14 / 출력 10 = 릴레이 6 + TR 4) | C6: =VLOOKUP(A6,단가표!$B$5:$G$25,6,FALSE()) -> 342000 | D6: 0 | E6: =C6*D6 -> 0 | F6: =1*요약!$C$6+1*요약!$C$8 -> 250 | G6: =C6*F6 -> 85500000 | H6: TSU, ANU-S
A7: TM241C40T | B7: =VLOOKUP(A7,단가표!$B$5:$G$25,3,FALSE()) -> CPU (입력 24 / 출력 16) | C7: =VLOOKUP(A7,단가표!$B$5:$G$25,6,FALSE()) -> 371200 | D7: =1*요약!$C$7 -> 300 | E7: =C7*D7 -> 111360000 | F7: 0 | G7: =C7*F7 -> 0 | H7: ANU
A8: TM241C40R | B8: =VLOOKUP(A8,단가표!$B$5:$G$25,3,FALSE()) -> CPU (입력 24 / 출력 16 = 릴레이 12 + TR 4) | C8: =VLOOKUP(A8,단가표!$B$5:$G$25,6,FALSE()) -> 361200 | D8: 0 | E8: =C8*D8 -> 0 | F8: =1*요약!$C$7 -> 300 | G8: =C8*F8 -> 108360000 | H8: ANU
A9: TM241CE40T | B9: =VLOOKUP(A9,단가표!$B$5:$G$25,3,FALSE()) -> CPU + 이더넷 (입력 24 / 출력 16) | C9: =VLOOKUP(A9,단가표!$B$5:$G$25,6,FALSE()) -> 368000 | D9: =1*요약!$C$9 -> 100 | E9: =C9*D9 -> 36800000 | F9: =1*요약!$C$9 -> 100 | G9: =C9*F9 -> 36800000 | H9: MCC
A10: TM3DI16 | B10: =VLOOKUP(A10,단가표!$B$5:$G$25,3,FALSE()) -> 디지털 입력 16점 | C10: =VLOOKUP(A10,단가표!$B$5:$G$25,6,FALSE()) -> 79800 | D10: =5*요약!$C$9 -> 500 | E10: =C10*D10 -> 39900000 | F10: =5*요약!$C$9 -> 500 | G10: =C10*F10 -> 39900000 | H10: MCC×5
A11: TM3DQ16T | B11: =VLOOKUP(A11,단가표!$B$5:$G$25,3,FALSE()) -> 트랜지스터 출력 16점 | C11: =VLOOKUP(A11,단가표!$B$5:$G$25,6,FALSE()) -> 79450 | D11: =2*요약!$C$9 -> 200 | E11: =C11*D11 -> 15890000 | F11: =2*요약!$C$9 -> 200 | G11: =C11*F11 -> 15890000 | H11: MCC×2
A12: TM3DQ8T | B12: =VLOOKUP(A12,단가표!$B$5:$G$25,3,FALSE()) -> 트랜지스터 출력 8점 | C12: =VLOOKUP(A12,단가표!$B$5:$G$25,6,FALSE()) -> 58800 | D12: =1*요약!$C$9 -> 100 | E12: =C12*D12 -> 5880000 | F12: =1*요약!$C$9 -> 100 | G12: =C12*F12 -> 5880000 | H12: MCC
A13: TM3AQ2 | B13: =VLOOKUP(A13,단가표!$B$5:$G$25,3,FALSE()) -> 아날로그 출력 2CH | C13: =VLOOKUP(A13,단가표!$B$5:$G$25,6,FALSE()) -> 121100 | D13: =1*요약!$C$8 -> 50 | E13: =C13*D13 -> 6055000 | F13: =1*요약!$C$8 -> 50 | G13: =C13*F13 -> 6055000 | H13: ANU-S
A14: TM3AQ4 | B14: =VLOOKUP(A14,단가표!$B$5:$G$25,3,FALSE()) -> 아날로그 출력 4CH | C14: =VLOOKUP(A14,단가표!$B$5:$G$25,6,FALSE()) -> 122850 | D14: =1*요약!$C$9 -> 100 | E14: =C14*D14 -> 12285000 | F14: =1*요약!$C$9 -> 100 | G14: =C14*F14 -> 12285000 | H14: MCC
A15: TM3XTRA1 | B15: =VLOOKUP(A15,단가표!$B$5:$G$25,3,FALSE()) -> TM3 버스 확장 송신 | C15: =VLOOKUP(A15,단가표!$B$5:$G$25,6,FALSE()) -> 54600 | D15: =1*요약!$C$9 -> 100 | E15: =C15*D15 -> 5460000 | F15: =1*요약!$C$9 -> 100 | G15: =C15*F15 -> 5460000 | H15: MCC
A16: TM3XREC1 | B16: =VLOOKUP(A16,단가표!$B$5:$G$25,3,FALSE()) -> TM3 버스 확장 수신 | C16: =VLOOKUP(A16,단가표!$B$5:$G$25,6,FALSE()) -> 64750 | D16: =1*요약!$C$9 -> 100 | E16: =C16*D16 -> 6475000 | F16: =1*요약!$C$9 -> 100 | G16: =C16*F16 -> 6475000 | H16: MCC
A17: 합계 | D17: =SUM(D5:D16) -> 1800 | E17: =SUM(E5:E16) -> 327405000 | F17: =SUM(F5:F16) -> 1800 | G17: =SUM(G5:G16) -> 322605000
A19: ※ 단가는 '단가표' 매입 단가 (TM241CE40T · TM3XTRA1 · TM3XREC1은 2026-10-06 추가 견적).
A20: ※ AC220V 납품 시에도 MCC는 DC24V(TM241CE40T)입니다.

Sheet CPU 할인 효과
A1: CPU 할인율을 더 받으면 얼마나 싸지나 (현재 = Schneider 협의값)
A3: 현재 할인율 (협의) | B3: 0.4
A4: 목표 할인율 | B4: 0.35 | C4: ← 숫자를 바꿔 보세요
A6: CPU 모델 | B6: 전원 | C6: 리스트가 | D6: 현재 매입가 | E6: 목표 매입가 | F6: 1대당 절감 | G6: 연간 수량 (대) | H6: 연간 절감
A7: TM241C24T | B7: DC | C7: =VLOOKUP(A7,단가표!$B$5:$G$25,4,FALSE()) -> 873000 | D7: =ROUND(C7*$B$3,0) -> 349200 | E7: =ROUND(C7*$B$4,0) -> 305550 | F7: =D7-E7 -> 43650 | G7: =요약!C6+요약!C8 -> 250 | H7: =F7*G7 -> 10912500 | I7: TSU + ANU-S (DC24V)
A8: TM241C40T | B8: DC | C8: =VLOOKUP(A8,단가표!$B$5:$G$25,4,FALSE()) -> 928000 | D8: =ROUND(C8*$B$3,0) -> 371200 | E8: =ROUND(C8*$B$4,0) -> 324800 | F8: =D8-E8 -> 46400 | G8: =요약!C7 -> 300 | H8: =F8*G8 -> 13920000 | I8: ANU (DC24V)
A9: TM241CE40T | B9: DC | C9: =VLOOKUP(A9,단가표!$B$5:$G$25,4,FALSE()) -> 920000 | D9: =ROUND(C9*$B$3,0) -> 368000 | E9: =ROUND(C9*$B$4,0) -> 322000 | F9: =D9-E9 -> 46000 | G9: =요약!C9 -> 100 | H9: =F9*G9 -> 4600000 | I9: MCC
A10: TM241C24R | B10: AC | C10: =VLOOKUP(A10,단가표!$B$5:$G$25,4,FALSE()) -> 855000 | D10: =ROUND(C10*$B$3,0) -> 342000 | E10: =ROUND(C10*$B$4,0) -> 299250 | F10: =D10-E10 -> 42750 | G10: =요약!C6+요약!C8 -> 250 | H10: =F10*G10 -> 10687500 | I10: TSU + ANU-S (AC220V)
A11: TM241C40R | B11: AC | C11: =VLOOKUP(A11,단가표!$B$5:$G$25,4,FALSE()) -> 903000 | D11: =ROUND(C11*$B$3,0) -> 361200 | E11: =ROUND(C11*$B$4,0) -> 316050 | F11: =D11-E11 -> 45150 | G11: =요약!C7 -> 300 | H11: =F11*G11 -> 13545000 | I11: ANU (AC220V)
A13: DC24V로 살 때 연간 추가 절감 (TM241C24T + C40T + CE40T) | H13: =H7+H8+H9 -> 29432500
A14: AC220V로 살 때 연간 추가 절감 (TM241C24R + C40R + MCC CE40T) | H14: =H9+H10+H11 -> 28832500
A16: ※ 확장 모듈(TM3)의 협의 할인율 0.35는 그대로 두고, CPU만 계산했습니다.

Sheet 단가표
A1: 단가표 (견적 리스트가 × Schneider 협의 할인율)
A2: 매입 단가 = 리스트가 × 할인율 — Schneider 협의 (2026-10-06): CPU 0.40 / 확장 모듈 0.35
A4: No. | B4: 모델 | C4: 전원 | D4: 설명 | E4: 리스트가 | F4: 할인율 (DF) | G4: 매입 단가
A5: 1 | B5: TM241CE24T | C5: DC | D5: CPU + 이더넷 (입력 14 / 출력 10) | E5: 886000 | F5: 0.4 | G5: =ROUND(E5*F5,0) -> 354400
A6: 2 | B6: TM241C24T | C6: DC | D6: CPU (입력 14 / 출력 10) | E6: 873000 | F6: 0.4 | G6: =ROUND(E6*F6,0) -> 349200
A7: 3 | B7: TM241C24R | C7: AC | D7: CPU (입력 14 / 출력 10 = 릴레이 6 + TR 4) | E7: 855000 | F7: 0.4 | G7: =ROUND(E7*F7,0) -> 342000
A8: 4 | B8: TM241C40T | C8: DC | D8: CPU (입력 24 / 출력 16) | E8: 928000 | F8: 0.4 | G8: =ROUND(E8*F8,0) -> 371200
A9: 5 | B9: TM241C40R | C9: AC | D9: CPU (입력 24 / 출력 16 = 릴레이 12 + TR 4) | E9: 903000 | F9: 0.4 | G9: =ROUND(E9*F9,0) -> 361200
A10: 6 | B10: TM3DI16 | C10: - | D10: 디지털 입력 16점 | E10: 228000 | F10: 0.35 | G10: =ROUND(E10*F10,0) -> 79800
A11: 7 | B11: TM3DI8 | C11: - | D11: 디지털 입력 8점 | E11: 202000 | F11: 0.35 | G11: =ROUND(E11*F11,0) -> 70700
A12: 8 | B12: TM3DQ16R | C12: - | D12: 릴레이 출력 16점 | E12: 227000 | F12: 0.35 | G12: =ROUND(E12*F12,0) -> 79450
A13: 9 | B13: TM3DQ16T | C13: - | D13: 트랜지스터 출력 16점 | E13: 227000 | F13: 0.35 | G13: =ROUND(E13*F13,0) -> 79450
A14: 10 | B14: TM3DQ16U | C14: - | D14: 트랜지스터 출력 16점 (Sink) | E14: 213000 | F14: 0.35 | G14: =ROUND(E14*F14,0) -> 74550
A15: 11 | B15: TM3DQ8R | C15: - | D15: 릴레이 출력 8점 | E15: 161000 | F15: 0.35 | G15: =ROUND(E15*F15,0) -> 56350
A16: 12 | B16: TM3DQ8T | C16: - | D16: 트랜지스터 출력 8점 | E16: 168000 | F16: 0.35 | G16: =ROUND(E16*F16,0) -> 58800
... A25: 21 | B25: TM3XREC1 | C25: - | D25: TM3 버스 확장 수신 | E25: 185000 | F25: 0.35 | G25: =ROUND(E25*F25,0) -> 64750
A26: ※ 1~18번 기존 견적, 19~21번(TM241CE40T · TM3XTRA1 · TM3XREC1)은 2026-10-06 추가 견적. 참고 NP: 579,600 / 98,280 / 116,550
